Workbook

Sheet Results_list
G2: Scenario
B3: Activity | C3: Activity | D3: Impact Category | F3: Impact Mitigation | G3: SSP1 | H3: SSP1 + VSI | I3: Δ% | J3: SSP2 | K3: SSP2 + VSI | L3: Δ% | M3: SSP5 | N3: SSP5 + VSI | O3: Δ%
B4: platinum group metal mine operation, ore with high palladium content (RU) | C4: platinum group metal mine operation, ore with high palladium content | D4: ('ReCiPe Midpoint (H)', 'terrestrial ecotoxicity', 'TETPinf') | F4: TETPinf | G4: =((SUMIFS(SSP1_Baseline!$E:$E,SSP1_Baseline!$C:$C,Results_list!$C$4,SSP1_Baseline!$D:$D,Results_list!$D4,SSP1_Baseline!$B:$B,2040)) - (SUMIFS(SSP1_Baseline!$E:$E,SSP1_Baseline!$C:$C,Results_list!$C$4,SSP1_Baseline!$D:$D,Results_list!$D4,SSP1_Baseline!$B:$B,2025))) / (SUMIFS(SSP1_Baseline!$E:$E,SSP1_Baseline!$C:$C,Results_list!$C$4,SSP1_Baseline!$D:$D,Results_list!$D4,SSP1_Baseline!$B:$B,2025)) -> -0.086069654 | H4: =((SUMIFS(SSP1_VSI!$F:$F,SSP1_VSI!$C:$C,Results_list!$C$4,SSP1_VSI!$D:$D,Results_list!$D4,SSP1_VSI!$B:$B,2040)) - (SUMIFS(SSP1_VSI!$F:$F,SSP1_VSI!$C:$C,Results_list!$C$4,SSP1_VSI!$D:$D,Results_list!$D4,SSP1_VSI!$B:$B,2025))) / (SUMIFS(SSP1_VSI!$F:$F,SSP1_VSI!$C:$C,Results_list!$C$4,SSP1_VSI!$D:$D,Results_list!$D4,SSP1_VSI!$B:$B,2025)) -> -0.32276358 | I4: =ROUND(H4-G4,2) -> -0.24 | J4: =((SUMIFS(SSP2_Baseline!$E:$E,SSP2_Baseline!$C:$C,Results_list!$C$4,SSP2_Baseline!$D:$D,Results_list!$D4,SSP2_Baseline!$B:$B,2040)) - (SUMIFS(SSP2_Baseline!$E:$E,SSP2_Baseline!$C:$C,Results_list!$C$4,SSP2_Baseline!$D:$D,Results_list!$D4,SSP2_Baseline!$B:$B,2025))) / (SUMIFS(SSP2_Baseline!$E:$E,SSP2_Baseline!$C:$C,Results_list!$C$4,SSP2_Baseline!$D:$D,Results_list!$D4,SSP2_Baseline!$B:$B,2025)) -> 0.32899823 | K4: =((SUMIFS(SSP2_VSI!$F:$F,SSP2_VSI!$C:$C,Results_list!$C$4,SSP2_VSI!$D:$D,Results_list!$D4,SSP2_VSI!$B:$B,2040)) - (SUMIFS(SSP2_VSI!$F:$F,SSP2_VSI!$C:$C,Results_list!$C$4,SSP2_VSI!$D:$D,Results_list!$D4,SSP2_VSI!$B:$B,2025))) / (SUMIFS(SSP2_VSI!$F:$F,SSP2_VSI!$C:$C,Results_list!$C$4,SSP2_VSI!$D:$D,Results_list!$D4,SSP2_VSI!$B:$B,2025)) -> -0.12398302 | L4: =ROUND(K4-J4,2) -> -0.45 | M4: =((SUMIFS(SSP5_Baseline!$E:$E,SSP5_Baseline!$C:$C,Results_list!$C$4,SSP5_Baseline!$D:$D,Results_list!$D4,SSP5_Baseline!$B:$B,2040)) - (SUMIFS(SSP5_Baseline!$E:$E,SSP5_Baseline!$C:$C,Results_list!$C$4,SSP5_Baseline!$D:$D,Results_list!$D4,SSP5_Baseline!$B:$B,2025))) / (SUMIFS(SSP5_Baseline!$E:$E,SSP5_Baseline!$C:$C,Results_list!$C$4,SSP5_Baseline!$D:$D,Results_list!$D4,SSP5_Baseline!$B:$B,2025)) -> 0.53114618 | N4: =((SUMIFS(SSP5_VSI!$F:$F,SSP5_VSI!$C:$C,Results_list!$C$4,SSP5_VSI!$D:$D,Results_list!$D4,SSP5_VSI!$B:$B,2040)) - (SUMIFS(SSP5_VSI!$F:$F,SSP5_VSI!$C:$C,Results_list!$C$4,SSP5_VSI!$D:$D,Results_list!$D4,SSP5_VSI!$B:$B,2025))) / (SUMIFS(SSP5_VSI!$F:$F,SSP5_VSI!$C:$C,Results_list!$C$4,SSP5_VSI!$D:$D,Results_list!$D4,SSP5_VSI!$B:$B,2025)) -> 0.056086358 | O4: =ROUND(N4-M4,2) -> -0.48
D5: ('ReCiPe Midpoint (H)', 'natural land transformation', 'NLTP') | F5: NLTP | G5: =((SUMIFS(SSP1_Baseline!E:E,SSP1_Baseline!C:C,Results_list!$C$4,SSP1_Baseline!D:D,Results_list!D5,SSP1_Baseline!B:B,2040)) - (SUMIFS(SSP1_Baseline!E:E,SSP1_Baseline!C:C,Results_list!$C$4,SSP1_Baseline!D:D,Results_list!D5,SSP1_Baseline!B:B,2025))) / (SUMIFS(SSP1_Baseline!E:E,SSP1_Baseline!C:C,Results_list!$C$4,SSP1_Baseline!D:D,Results_list!D5,SSP1_Baseline!B:B,2025)) -> -0.063355467 | H5: =((SUMIFS(SSP1_VSI!F:F,SSP1_VSI!C:C,Results_list!$C$4,SSP1_VSI!D:D,Results_list!D5,SSP1_VSI!B:B,2040)) - (SUMIFS(SSP1_VSI!F:F,SSP1_VSI!C:C,Results_list!$C$4,SSP1_VSI!D:D,Results_list!D5,SSP1_VSI!B:B,2025))) / (SUMIFS(SSP1_VSI!F:F,SSP1_VSI!C:C,Results_list!$C$4,SSP1_VSI!D:D,Results_list!D5,SSP1_VSI!B:B,2025)) -> -0.063357724 | I5: =ROUND(H5-G5,2) -> 0 | J5: =((SUMIFS(SSP2_Baseline!$E:$E,SSP2_Baseline!$C:$C,Results_list!$C$4,SSP2_Baseline!$D:$D,Results_list!$D5,SSP2_Baseline!$B:$B,2040)) - (SUMIFS(SSP2_Baseline!$E:$E,SSP2_Baseline!$C:$C,Results_list!$C$4,SSP2_Baseline!$D:$D,Results_list!$D5,SSP2_Baseline!$B:$B,2025))) / (SUMIFS(SSP2_Baseline!$E:$E,SSP2_Baseline!$C:$C,Results_list!$C$4,SSP2_Baseline!$D:$D,Results_list!$D5,SSP2_Baseline!$B:$B,2025)) -> -0.072682945 | K5: =((SUMIFS(SSP2_VSI!$F:$F,SSP2_VSI!$C:$C,Results_list!$C$4,SSP2_VSI!$D:$D,Results_list!$D5,SSP2_VSI!$B:$B,2040)) - (SUMIFS(SSP2_VSI!$F:$F,SSP2_VSI!$C:$C,Results_list!$C$4,SSP2_VSI!$D:$D,Results_list!$D5,SSP2_VSI!$B:$B,2025))) / (SUMIFS(SSP2_VSI!$F:$F,SSP2_VSI!$C:$C,Results_list!$C$4,SSP2_VSI!$D:$D,Results_list!$D5,SSP2_VSI!$B:$B,2025)) -> -0.072677615 | L5: =ROUND(K5-J5,2) -> 0 | M5: =((SUMIFS(SSP5_Baseline!$E:$E,SSP5_Baseline!$C:$C,Results_list!$C$4,SSP5_Baseline!$D:$D,Results_list!$D5,SSP5_Baseline!$B:$B,2040)) - (SUMIFS(SSP5_Baseline!$E:$E,SSP5_Baseline!$C:$C,Results_list!$C$4,SSP5_Baseline!$D:$D,Results_list!$D5,SSP5_Baseline!$B:$B,2025))) / (SUMIFS(SSP5_Baseline!$E:$E,SSP5_Baseline!$C:$C,Results_list!$C$4,SSP5_Baseline!$D:$D,Results_list!$D5,SSP5_Baseline!$B:$B,2025)) -> 0.16400753 | N5: =((SUMIFS(SSP5_VSI!$F:$F,SSP5_VSI!$C:$C,Results_list!$C$4,SSP5_VSI!$D:$D,Results_list!$D5,SSP5_VSI!$B:$B,2040)) - (SUMIFS(SSP5_VSI!$F:$F,SSP5_VSI!$C:$C,Results_list!$C$4,SSP5_VSI!$D:$D,Results_list!$D5,SSP5_VSI!$B:$B,2025))) / (SUMIFS(SSP5_VSI!$F:$F,SSP5_VSI!$C:$C,Results_list!$C$4,SSP5_VSI!$D:$D,Results_list!$D5,SSP5_VSI!$B:$B,2025)) -> 0.163929 | O5: =ROUND(N5-M5,2) -> 0
D6: ('ReCiPe Midpoint (H)', 'photochemical oxidant formation', 'POFP') | F6: POFP | G6: =((SUMIFS(SSP1_Baseline!E:E,SSP1_Baseline!C:C,Results_list!$C$4,SSP1_Baseline!D:D,Results_list!D6,SSP1_Baseline!B:B,2040)) - (SUMIFS(SSP1_Baseline!E:E,SSP1_Baseline!C:C,Results_list!$C$4,SSP1_Baseline!D:D,Results_list!D6,SSP1_Baseline!B:B,2025))) / (SUMIFS(SSP1_Baseline!E:E,SSP1_Baseline!C:C,Results_list!$C$4,SSP1_Baseline!D:D,Results_list!D6,SSP1_Baseline!B:B,2025)) -> -0.0032533836 | H6: =((SUMIFS(SSP1_VSI!F:F,SSP1_VSI!C:C,Results_list!$C$4,SSP1_VSI!D:D,Results_list!D6,SSP1_VSI!B:B,2040)) - (SUMIFS(SSP1_VSI!F:F,SSP1_VSI!C:C,Results_list!$C$4,SSP1_VSI!D:D,Results_list!D6,SSP1_VSI!B:B,2025))) / (SUMIFS(SSP1_VSI!F:F,SSP1_VSI!C:C,Results_list!$C$4,SSP1_VSI!D:D,Results_list!D6,SSP1_VSI!B:B,2025)) -> -0.93631373 | I6: =ROUND(H6-G6,2) -> -0.93 | J6: =((SUMIFS(SSP2_Baseline!$E:$E,SSP2_Baseline!$C:$C,Results_list!$C$4,SSP2_Baseline!$D:$D,Results_list!$D6,SSP2_Baseline!$B:$B,2040)) - (SUMIFS(SSP2_Baseline!$E:$E,SSP2_Baseline!$C:$C,Results_list!$C$4,SSP2_Baseline!$D:$D,Results_list!$D6,SSP2_Baseline!$B:$B,2025))) / (SUMIFS(SSP2_Baseline!$E:$E,SSP2_Baseline!$C:$C,Results_list!$C$4,SSP2_Baseline!$D:$D,Results_list!$D6,SSP2_Baseline!$B:$B,2025)) -> -0.0030202638 | K6: =((SUMIFS(SSP2_VSI!$F:$F,SSP2_VSI!$C:$C,Results_list!$C$4,SSP2_VSI!$D:$D,Results_list!$D6,SSP2_VSI!$B:$B,2040)) - (SUMIFS(SSP2_VSI!$F:$F,SSP2_VSI!$C:$C,Results_list!$C$4,SSP2_VSI!$D:$D,Results_list!$D6,SSP2_VSI!$B:$B,2025))) / (SUMIFS(SSP2_VSI!$F:$F,SSP2_VSI!$C:$C,Results_list!$C$4,SSP2_VSI!$D:$D,Results_list!$D6,SSP2_VSI!$B:$B,2025)) -> -0.93595552 | L6: =ROUND(K6-J6,2) -> -0.93 | M6: =((SUMIFS(SSP5_Baseline!$E:$E,SSP5_Baseline!$C:$C,Results_list!$C$4,SSP5_Baseline!$D:$D,Results_list!$D6,SSP5_Baseline!$B:$B,2040)) - (SUMIFS(SSP5_Baseline!$E:$E,SSP5_Baseline!$C:$C,Results_list!$C$4,SSP5_Baseline!$D:$D,Results_list!$D6,SSP5_Baseline!$B:$B,2025))) / (SUMIFS(SSP5_Baseline!$E:$E,SSP5_Baseline!$C:$C,Results_list!$C$4,SSP5_Baseline!$D:$D,Results_list!$D6,SSP5_Baseline!$B:$B,2025)) -> 0.00015985024 | N6: =((SUMIFS(SSP5_VSI!$F:$F,SSP5_VSI!$C:$C,Results_list!$C$4,SSP5_VSI!$D:$D,Results_list!$D6,SSP5_VSI!$B:$B,2040)) - (SUMIFS(SSP5_VSI!$F:$F,SSP5_VSI!$C:$C,Results_list!$C$4,SSP5_VSI!$D:$D,Results_list!$D6,SSP5_VSI!$B:$B,2025))) / (SUMIFS(SSP5_VSI!$F:$F,SSP5_VSI!$C:$C,Results_list!$C$4,SSP5_VSI!$D:$D,Results_list!$D6,SSP5_VSI!$B:$B,2025)) -> -0.9303396 | O6: =ROUND(N6-M6,2) -> -0.93
D7: ('ReCiPe Midpoint (H)', 'human toxicity', 'HTPinf') | F7: HTPinf | G7: =((SUMIFS(SSP1_Baseline!E:E,SSP1_Baseline!C:C,Results_list!$C$4,SSP1_Baseline!D:D,Results_list!D7,SSP1_Baseline!B:B,2040)) - (SUMIFS(SSP1_Baseline!E:E,SSP1_Baseline!C:C,Results_list!$C$4,SSP1_Baseline!D:D,Results_list!D7,SSP1_Baseline!B:B,2025))) / (SUMIFS(SSP1_Baseline!E:E,SSP1_Baseline!C:C,Results_list!$C$4,SSP1_Baseline!D:D,Results_list!D7,SSP1_Baseline!B:B,2025)) -> -0.063126918 | H7: =((SUMIFS(SSP1_VSI!F:F,SSP1_VSI!C:C,Results_list!$C$4,SSP1_VSI!D:D,Results_list!D7,SSP1_VSI!B:B,2040)) - (SUMIFS(SSP1_VSI!F:F,SSP1_VSI!C:C,Results_list!$C$4,SSP1_VSI!D:D,Results_list!D7,SSP1_VSI!B:B,2025))) / (SUMIFS(SSP1_VSI!F:F,SSP1_VSI!C:C,Results_list!$C$4,SSP1_VSI!D:D,Results_list!D7,SSP1_VSI!B:B,2025)) -> -0.18415985 | I7: =ROUND(H7-G7,2) -> -0.12 | J7: =((SUMIFS(SSP2_Baseline!$E:$E,SSP2_Baseline!$C:$C,Results_list!$C$4,SSP2_Baseline!$D:$D,Results_list!$D7,SSP2_Baseline!$B:$B,2040)) - (SUMIFS(SSP2_Baseline!$E:$E,SSP2_Baseline!$C:$C,Results_list!$C$4,SSP2_Baseline!$D:$D,Results_list!$D7,SSP2_Baseline!$B:$B,2025))) / (SUMIFS(SSP2_Baseline!$E:$E,SSP2_Baseline!$C:$C,Results_list!$C$4,SSP2_Baseline!$D:$D,Results_list!$D7,SSP2_Baseline!$B:$B,2025)) -> -0.05871192 | K7: =((SUMIFS(SSP2_VSI!$F:$F,SSP2_VSI!$C:$C,Results_list!$C$4,SSP2_VSI!$D:$D,Results_list!$D7,SSP2_VSI!$B:$B,2040)) - (SUMIFS(SSP2_VSI!$F:$F,SSP2_VSI!$C:$C,Results_list!$C$4,SSP2_VSI!$D:$D,Results_list!$D7,SSP2_VSI!$B:$B,2025))) / (SUMIFS(SSP2_VSI!$F:$F,SSP2_VSI!$C:$C,Results_list!$C$4,SSP2_VSI!$D:$D,Results_list!$D7,SSP2_VSI!$B:$B,2025)) -> -0.17971458 | L7: =ROUND(K7-J7,2) -> -0.12 | M7: =((SUMIFS(SSP5_Baseline!$E:$E,SSP5_Baseline!$C:$C,Results_list!$C$4,SSP5_Baseline!$D:$D,Results_list!$D7,SSP5_Baseline!$B:$B,2040)) - (SUMIFS(SSP5_Baseline!$E:$E,SSP5_Baseline!$C:$C,Results_list!$C$4,SSP5_Baseline!$D:$D,Results_list!$D7,SSP5_Baseline!$B:$B,2025))) / (SUMIFS(SSP5_Baseline!$E:$E,SSP5_Baseline!$C:$C,Results_list!$C$4,SSP5_Baseline!$D:$D,Results_list!$D7,SSP5_Baseline!$B:$B,2025)) -> -0.05556281 | N7: =((SUMIFS(SSP5_VSI!$F:$F,SSP5_VSI!$C:$C,Results_list!$C$4,SSP5_VSI!$D:$D,Results_list!$D7,SSP5_VSI!$B:$B,2040)) - (SUMIFS(SSP5_VSI!$F:$F,SSP5_VSI!$C:$C,Results_list!$C$4,SSP5_VSI!$D:$D,Results_list!$D7,SSP5_VSI!$B:$B,2025))) / (SUMIFS(SSP5_VSI!$F:$F,SSP5_VSI!$C:$C,Results_list!$C$4,SSP5_VSI!$D:$D,Results_list!$D7,SSP5_VSI!$B:$B,2025)) -> -0.16680077 | O7: =ROUND(N7-M7,2) -> -0.11
D8: ('ReCiPe Midpoint (H)', 'marine eutrophication', 'MEP') | F8: MEP | G8: =((SUMIFS(SSP1_Baseline!E:E,SSP1_Baseline!C:C,Results_list!$C$4,SSP1_Baseline!D:D,Results_list!D8,SSP1_Baseline!B:B,2040)) - (SUMIFS(SSP1_Baseline!E:E,SSP1_Baseline!C:C,Results_list!$C$4,SSP1_Baseline!D:D,Results_list!D8,SSP1_Baseline!B:B,2025))) / (SUMIFS(SSP1_Baseline!E:E,SSP1_Baseline!C:C,Results_list!$C$4,SSP1_Baseline!D:D,Results_list!D8,SSP1_Baseline!B:B,2025)) -> -0.1513448 | H8: =((SUMIFS(SSP1_VSI!F:F,SSP1_VSI!C:C,Results_list!$C$4,SSP1_VSI!D:D,Results_list!D8,SSP1_VSI!B:B,2040)) - (SUMIFS(SSP1_VSI!F:F,SSP1_VSI!C:C,Results_list!$C$4,SSP1_VSI!D:D,Results_list!D8,SSP1_VSI!B:B,2025))) / (SUMIFS(SSP1_VSI!F:F,SSP1_VSI!C:C,Results_list!$C$4,SSP1_VSI!D:D,Results_list!D8,SSP1_VSI!B:B,2025)) -> -0.19315105 | I8: =ROUND(H8-G8,2) -> -0.04 | J8: =((SUMIFS(SSP2_Baseline!$E:$E,SSP2_Baseline!$C:$C,Results_list!$C$4,SSP2_Baseline!$D:$D,Results_list!$D8,SSP2_Baseline!$B:$B,2040)) - (SUMIFS(SSP2_Baseline!$E:$E,SSP2_Baseline!$C:$C,Results_list!$C$4,SSP2_Baseline!$D:$D,Results_list!$D8,SSP2_Baseline!$B:$B,2025))) / (SUMIFS(SSP2_Baseline!$E:$E,SSP2_Baseline!$C:$C,Results_list!$C$4,SSP2_Baseline!$D:$D,Results_list!$D8,SSP2_Baseline!$B:$B,2025)) -> -0.1097466 | K8: =((SUMIFS(SSP2_VSI!$F:$F,SSP2_VSI!$C:$C,Results_list!$C$4,SSP2_VSI!$D:$D,Results_list!$D8,SSP2_VSI!$B:$B,2040)) - (SUMIFS(SSP2_VSI!$F:$F,SSP2_VSI!$C:$C,Results_list!$C$4,SSP2_VSI!$D:$D,Results_list!$D8,SSP2_VSI!$B:$B,2025))) / (SUMIFS(SSP2_VSI!$F:$F,SSP2_VSI!$C:$C,Results_list!$C$4,SSP2_VSI!$D:$D,Results_list!$D8,SSP2_VSI!$B:$B,2025)) -> -0.15413152 | L8: =ROUND(K8-J8,2) -> -0.04 | M8: =((SUMIFS(SSP5_Baseline!$E:$E,SSP5_Baseline!$C:$C,Results_list!$C$4,SSP5_Baseline!$D:$D,Results_list!$D8,SSP5_Baseline!$B:$B,2040)) - (SUMIFS(SSP5_Baseline!$E:$E,SSP5_Baseline!$C:$C,Results_list!$C$4,SSP5_Baseline!$D:$D,Results_list!$D8,SSP5_Baseline!$B:$B,2025))) / (SUMIFS(SSP5_Baseline!$E:$E,SSP5_Baseline!$C:$C,Results_list!$C$4,SSP5_Baseline!$D:$D,Results_list!$D8,SSP5_Baseline!$B:$B,2025)) -> -0.074212603 | N8: =((SUMIFS(SSP5_VSI!$F:$F,SSP5_VSI!$C:$C,Results_list!$C$4,SSP5_VSI!$D:$D,Results_list!$D8,SSP5_VSI!$B:$B,2040)) - (SUMIFS(SSP5_VSI!$F:$F,SSP5_VSI!$C:$C,Results_list!$C$4,SSP5_VSI!$D:$D,Results_list!$D8,SSP5_VSI!$B:$B,2025))) / (SUMIFS(SSP5_VSI!$F:$F,SSP5_VSI!$C:$C,Results_list!$C$4,SSP5_VSI!$D:$D,Results_list!$D8,SSP5_VSI!$B:$B,2025)) -> -0.11293629 | O8: =ROUND(N8-M8,2) -> -0.04
D9: ('IPCC 2013', 'climate change', 'GWP 100a, incl. H and bio CO2') | F9: GWP100 | G9: =((SUMIFS(SSP1_Baseline!E:E,SSP1_Baseline!C:C,Results_list!$C$4,SSP1_Baseline!D:D,Results_list!D9,SSP1_Baseline!B:B,2040)) - (SUMIFS(SSP1_Baseline!E:E,SSP1_Baseline!C:C,Results_list!$C$4,SSP1_Baseline!D:D,Results_list!D9,SSP1_Baseline!B:B,2025))) / (SUMIFS(SSP1_Baseline!E:E,SSP1_Baseline!C:C,Results_list!$C$4,SSP1_Baseline!D:D,Results_list!D9,SSP1_Baseline!B:B,2025)) -> -0.083937643 | H9: =((SUMIFS(SSP1_VSI!F:F,SSP1_VSI!C:C,Results_list!$C$4,SSP1_VSI!D:D,Results_list!D9,SSP1_VSI!B:B,2040)) - (SUMIFS(SSP1_VSI!F:F,SSP1_VSI!C:C,Results_list!$C$4,SSP1_VSI!D:D,Results_list!D9,SSP1_VSI!B:B,2025))) / (SUMIFS(SSP1_VSI!F:F,SSP1_VSI!C:C,Results_list!$C$4,SSP1_VSI!D:D,Results_list!D9,SSP1_VSI!B:B,2025)) -> -0.096716075 | I9: =ROUND(H9-G9,2) -> -0.01 | J9: =((SUMIFS(SSP2_Baseline!$E:$E,SSP2_Baseline!$C:$C,Results_list!$C$4,SSP2_Baseline!$D:$D,Results_list!$D9,SSP2_Baseline!$B:$B,2040)) - (SUMIFS(SSP2_Baseline!$E:$E,SSP2_Baseline!$C:$C,Results_list!$C$4,SSP2_Baseline!$D:$D,Results_list!$D9,SSP2_Baseline!$B:$B,2025))) / (SUMIFS(SSP2_Baseline!$E:$E,SSP2_Baseline!$C:$C,Results_list!$C$4,SSP2_Baseline!$D:$D,Results_list!$D9,SSP2_Baseline!$B:$B,2025)) -> -0.066957304 | K9: =((SUMIFS(SSP2_VSI!$F:$F,SSP2_VSI!$C:$C,Results_list!$C$4,SSP2_VSI!$D:$D,Results_list!$D9,SSP2_VSI!$B:$B,2040)) - (SUMIFS(SSP2_VSI!$F:$F,SSP2_VSI!$C:$C,Results_list!$C$4,SSP2_VSI!$D:$D,Results_list!$D9,SSP2_VSI!$B:$B,2025))) / (SUMIFS(SSP2_VSI!$F:$F,SSP2_VSI!$C:$C,Results_list!$C$4,SSP2_VSI!$D:$D,Results_list!$D9,SSP2_VSI!$B:$B,2025)) -> -0.079768049 | L9: =ROUND(K9-J9,2) -> -0.01 | M9: =((SUMIFS(SSP5_Baseline!$E:$E,SSP5_Baseline!$C:$C,Results_list!$C$4,SSP5_Baseline!$D:$D,Results_list!$D9,SSP5_Baseline!$B:$B,2040)) - (SUMIFS(SSP5_Baseline!$E:$E,SSP5_Baseline!$C:$C,Results_list!$C$4,SSP5_Baseline!$D:$D,Results_list!$D9,SSP5_Baseline!$B:$B,2025))) / (SUMIFS(SSP5_Baseline!$E:$E,SSP5_Baseline!$C:$C,Results_list!$C$4,SSP5_Baseline!$D:$D,Results_list!$D9,SSP5_Baseline!$B:$B,2025)) -> 0.050519624 | N9: =((SUMIFS(SSP5_VSI!$F:$F,SSP5_VSI!$C:$C,Results_list!$C$4,SSP5_VSI!$D:$D,Results_list!$D9,SSP5_VSI!$B:$B,2040)) - (SUMIFS(SSP5_VSI!$F:$F,SSP5_VSI!$C:$C,Results_list!$C$4,SSP5_VSI!$D:$D,Results_list!$D9,SSP5_VSI!$B:$B,2025))) / (SUMIFS(SSP5_VSI!$F:$F,SSP5_VSI!$C:$C,Results_list!$C$4,SSP5_VSI!$D:$D,Results_list!$D9,SSP5_VSI!$B:$B,2025)) -> 0.038729879 | O9: =ROUND(N9-M9,2) -> -0.01
D10: ('ReCiPe Midpoint (H)', 'particulate matter formation', 'PMFP') | F10: PMFP | G10: =((SUMIFS(SSP1_Baseline!E:E,SSP1_Baseline!C:C,Results_list!$C$4,SSP1_Baseline!D:D,Results_list!D10,SSP1_Baseline!B:B,2040)) - (SUMIFS(SSP1_Baseline!E:E,SSP1_Baseline!C:C,Results_list!$C$4,SSP1_Baseline!D:D,Results_list!D10,SSP1_Baseline!B:B,2025))) / (SUMIFS(SSP1_Baseline!E:E,SSP1_Baseline!C:C,Results_list!$C$4,SSP1_Baseline!D:D,Results_list!D10,SSP1_Baseline!B:B,2025)) -> -0.0034870925 | H10: =((SUMIFS(SSP1_VSI!F:F,SSP1_VSI!C:C,Results_list!$C$4,SSP1_VSI!D:D,Results_list!D10,SSP1_VSI!B:B,2040)) - (SUMIFS(SSP1_VSI!F:F,SSP1_VSI!C:C,Results_list!$C$4,SSP1_VSI!D:D,Results_list!D10,SSP1_VSI!B:B,2025))) / (SUMIFS(SSP1_VSI!F:F,SSP1_VSI!C:C,Results_list!$C$4,SSP1_VSI!D:D,Results_list!D10,SSP1_VSI!B:B,2025)) -> -0.96194587 | I10: =ROUND(H10-G10,2) -> -0.96 | J10: =((SUMIFS(SSP2_Baseline!$E:$E,SSP2_Baseline!$C:$C,Results_list!$C$4,SSP2_Baseline!$D:$D,Results_list!$D10,SSP2_Baseline!$B:$B,2040)) - (SUMIFS(SSP2_Baseline!$E:$E,SSP2_Baseline!$C:$C,Results_list!$C$4,SSP2_Baseline!$D:$D,Results_list!$D10,SSP2_Baseline!$B:$B,2025))) / (SUMIFS(SSP2_Baseline!$E:$E,SSP2_Baseline!$C:$C,Results_list!$C$4,SSP2_Baseline!$D:$D,Results_list!$D10,SSP2_Baseline!$B:$B,2025)) -> -0.0036665373 | K10: =((SUMIFS(SSP2_VSI!$F:$F,SSP2_VSI!$C:$C,Results_list!$C$4,SSP2_VSI!$D:$D,Results_list!$D10,SSP2_VSI!$B:$B,2040)) - (SUMIFS(SSP2_VSI!$F:$F,SSP2_VSI!$C:$C,Results_list!$C$4,SSP2_VSI!$D:$D,Results_list!$D10,SSP2_VSI!$B:$B,2025))) / (SUMIFS(SSP2_VSI!$F:$F,SSP2_VSI!$C:$C,Results_list!$C$4,SSP2_VSI!$D:$D,Results_list!$D10,SSP2_VSI!$B:$B,2025)) -> -0.96246239 | L10: =ROUND(K10-J10,2) -> -0.96 | M10: =((SUMIFS(SSP5_Baseline!$E:$E,SSP5_Baseline!$C:$C,Results_list!$C$4,SSP5_Baseline!$D:$D,Results_list!$D10,SSP5_Baseline!$B:$B,2040)) - (SUMIFS(SSP5_Baseline!$E:$E,SSP5_Baseline!$C:$C,Results_list!$C$4,SSP5_Baseline!$D:$D,Results_list!$D10,SSP5_Baseline!$B:$B,2025))) / (SUMIFS(SSP5_Baseline!$E:$E,SSP5_Baseline!$C:$C,Results_list!$C$4,SSP5_Baseline!$D:$D,Results_list!$D10,SSP5_Baseline!$B:$B,2025)) -> -0.0039762497 | N10: =((SUMIFS(SSP5_VSI!$F:$F,SSP5_VSI!$C:$C,Results_list!$C$4,SSP5_VSI!$D:$D,Results_list!$D10,SSP5_VSI!$B:$B,2040)) - (SUMIFS(SSP5_VSI!$F:$F,SSP5_VSI!$C:$C,Results_list!$C$4,SSP5_VSI!$D:$D,Results_list!$D10,SSP5_VSI!$B:$B,2025))) / (SUMIFS(SSP5_VSI!$F:$F,SSP5_VSI!$C:$C,Results_list!$C$4,SSP5_VSI!$D:$D,Results_list!$D10,SSP5_VSI!$B:$B,2025)) -> -0.9586254 | O10: =ROUND(N10-M10,2) -> -0.95
D11: ('ReCiPe Midpoint (H)', 'agricultural land occupation', 'ALOP') | F11: ALOP | G11: =((SUMIFS(SSP1_Baseline!E:E,SSP1_Baseline!C:C,Results_list!$C$4,SSP1_Baseline!D:D,Results_list!D11,SSP1_Baseline!B:B,2040)) - (SUMIFS(SSP1_Baseline!E:E,SSP1_Baseline!C:C,Results_list!$C$4,SSP1_Baseline!D:D,Results_list!D11,SSP1_Baseline!B:B,2025))) / (SUMIFS(SSP1_Baseline!E:E,SSP1_Baseline!C:C,Results_list!$C$4,SSP1_Baseline!D:D,Results_list!D11,SSP1_Baseline!B:B,2025)) -> 0.65037748 | H11: =((SUMIFS(SSP1_VSI!F:F,SSP1_VSI!C:C,Results_list!$C$4,SSP1_VSI!D:D,Results_list!D11,SSP1_VSI!B:B,2040)) - (SUMIFS(SSP1_VSI!F:F,SSP1_VSI!C:C,Results_list!$C$4,SSP1_VSI!D:D,Results_list!D11,SSP1_VSI!B:B,2025))) / (SUMIFS(SSP1_VSI!F:F,SSP1_VSI!C:C,Results_list!$C$4,SSP1_VSI!D:D,Results_list!D11,SSP1_VSI!B:B,2025)) -> 0.65044171 | I11: =ROUND(H11-G11,2) -> 0 | J11: =((SUMIFS(SSP2_Baseline!$E:$E,SSP2_Baseline!$C:$C,Results_list!$C$4,SSP2_Baseline!$D:$D,Results_list!$D11,SSP2_Baseline!$B:$B,2040)) - (SUMIFS(SSP2_Baseline!$E:$E,SSP2_Baseline!$C:$C,Results_list!$C$4,SSP2_Baseline!$D:$D,Results_list!$D11,SSP2_Baseline!$B:$B,2025))) / (SUMIFS(SSP2_Baseline!$E:$E,SSP2_Baseline!$C:$C,Results_list!$C$4,SSP2_Baseline!$D:$D,Results_list!$D11,SSP2_Baseline!$B:$B,2025)) -> 0.58893618 | K11: =((SUMIFS(SSP2_VSI!$F:$F,SSP2_VSI!$C:$C,Results_list!$C$4,SSP2_VSI!$D:$D,Results_list!$D11,SSP2_VSI!$B:$B,2040)) - (SUMIFS(SSP2_VSI!$F:$F,SSP2_VSI!$C:$C,Results_list!$C$4,SSP2_VSI!$D:$D,Results_list!$D11,SSP2_VSI!$B:$B,2025))) / (SUMIFS(SSP2_VSI!$F:$F,SSP2_VSI!$C:$C,Results_list!$C$4,SSP2_VSI!$D:$D,Results_list!$D11,SSP2_VSI!$B:$B,2025)) -> 0.58869787 | L11: =ROUND(K11-J11,2) -> 0 | M11: =((SUMIFS(SSP5_Baseline!$E:$E,SSP5_Baseline!$C:$C,Results_list!$C$4,SSP5_Baseline!$D:$D,Results_list!$D11,SSP5_Baseline!$B:$B,2040)) - (SUMIFS(SSP5_Baseline!$E:$E,SSP5_Baseline!$C:$C,Results_list!$C$4,SSP5_Baseline!$D:$D,Results_list!$D11,SSP5_Baseline!$B:$B,2025))) / (SUMIFS(SSP5_Baseline!$E:$E,SSP5_Baseline!$C:$C,Results_list!$C$4,SSP5_Baseline!$D:$D,Results_list!$D11,SSP5_Baseline!$B:$B,2025)) -> 0.40918275 | N11: =((SUMIFS(SSP5_VSI!$F:$F,SSP5_VSI!$C:$C,Results_list!$C$4,SSP5_VSI!$D:$D,Results_list!$D11,SSP5_VSI!$B:$B,2040)) - (SUMIFS(SSP5_VSI!$F:$F,SSP5_VSI!$C:$C,Results_list!$C$4,SSP5_VSI!$D:$D,Results_list!$D11,SSP5_VSI!$B:$B,2025))) / (SUMIFS(SSP5_VSI!$F:$F,SSP5_VSI!$C:$C,Results_list!$C$4,SSP5_VSI!$D:$D,Results_list!$D11,SSP5_VSI!$B:$B,2025)) -> 0.40922026 | O11: =ROUND(N11-M11,2) -> 0
D12: ('ReCiPe Midpoint (H)', 'freshwater eutrophication', 'FEP') | F12: FEP | G12: =((SUMIFS(SSP1_Baseline!E:E,SSP1_Baseline!C:C,Results_list!$C$4,SSP1_Baseline!D:D,Results_list!D12,SSP1_Baseline!B:B,2040)) - (SUMIFS(SSP1_Baseline!E:E,SSP1_Baseline!C:C,Results_list!$C$4,SSP1_Baseline!D:D,Results_list!D12,SSP1_Baseline!B:B,2025))) / (SUMIFS(SSP1_Baseline!E:E,SSP1_Baseline!C:C,Results_list!$C$4,SSP1_Baseline!D:D,Results_list!D12,SSP1_Baseline!B:B,2025)) -> -0.23944373 | H12: =((SUMIFS(SSP1_VSI!F:F,SSP1_VSI!C:C,Results_list!$C$4,SSP1_VSI!D:D,Results_list!D12,SSP1_VSI!B:B,2040)) - (SUMIFS(SSP1_VSI!F:F,SSP1_VSI!C:C,Results_list!$C$4,SSP1_VSI!D:D,Results_list!D12,SSP1_VSI!B:B,2025))) / (SUMIFS(SSP1_VSI!F:F,SSP1_VSI!C:C,Results_list!$C$4,SSP1_VSI!D:D,Results_list!D12,SSP1_VSI!B:B,2025)) -> -0.23941733 | I12: =ROUND(H12-G12,2) -> 0 | J12: =((SUMIFS(SSP2_Baseline!$E:$E,SSP2_Baseline!$C:$C,Results_list!$C$4,SSP2_Baseline!$D:$D,Results_list!$D12,SSP2_Baseline!$B:$B,2040)) - (SUMIFS(SSP2_Baseline!$E:$E,SSP2_Baseline!$C:$C,Results_list!$C$4,SSP2_Baseline!$D:$D,Results_list!$D12,SSP2_Baseline!$B:$B,2025))) / (SUMIFS(SSP2_Baseline!$E:$E,SSP2_Baseline!$C:$C,Results_list!$C$4,SSP2_Baseline!$D:$D,Results_list!$D12,SSP2_Baseline!$B:$B,2025)) -> -0.24071122 | K12: =((SUMIFS(SSP2_VSI!$F:$F,SSP2_VSI!$C:$C,Results_list!$C$4,SSP2_VSI!$D:$D,Results_list!$D12,SSP2_VSI!$B:$B,2040)) - (SUMIFS(SSP2_VSI!$F:$F,SSP2_VSI!$C:$C,Results_list!$C$4,SSP2_VSI!$D:$D,Results_list!$D12,SSP2_VSI!$B:$B,2025))) / (SUMIFS(SSP2_VSI!$F:$F,SSP2_VSI!$C:$C,Results_list!$C$4,SSP2_VSI!$D:$D,Results_list!$D12,SSP2_VSI!$B:$B,2025)) -> -0.24070476 | L12: =ROUND(K12-J12,2) -> 0 | M12: =((SUMIFS(SSP5_Baseline!$E:$E,SSP5_Baseline!$C:$C,Results_list!$C$4,SSP5_Baseline!$D:$D,Results_list!$D12,SSP5_Baseline!$B:$B,2040)) - (SUMIFS(SSP5_Baseline!$E:$E,SSP5_Baseline!$C:$C,Results_list!$C$4,SSP5_Baseline!$D:$D,Results_list!$D12,SSP5_Baseline!$B:$B,2025))) / (SUMIFS(SSP5_Baseline!$E:$E,SSP5_Baseline!$C:$C,Results_list!$C$4,SSP5_Baseline!$D:$D,Results_list!$D12,SSP5_Baseline!$B:$B,2025)) -> -0.15345199 | N12: =((SUMIFS(SSP5_VSI!$F:$F,SSP5_VSI!$C:$C,Results_list!$C$4,SSP5_VSI!$D:$D,Results_list!$D12,SSP5_VSI!$B:$B,2040)) - (SUMIFS(SSP5_VSI!$F:$F,SSP5_VSI!$C:$C,Results_list!$C$4,SSP5_VSI!$D:$D,Results_list!$D12,SSP5_VSI!$B:$B,2025))) / (SUMIFS(SSP5_VSI!$F:$F,SSP5_VSI!$C:$C,Results_list!$C$4,SSP5_VSI!$D:$D,Results_list!$D12,SSP5_VSI!$B:$B,2025)) -> -0.15335376 | O12: =ROUND(N12-M12,2) -> 0
D13: ('ReCiPe Midpoint (H)', 'metal depletion', 'MDP') | F13: MDP | G13: =((SUMIFS(SSP1_Baseline!E:E,SSP1_Baseline!C:C,Results_list!$C$4,SSP1_Baseline!D:D,Results_list!D13,SSP1_Baseline!B:B,2040)) - (SUMIFS(SSP1_Baseline!E:E,SSP1_Baseline!C:C,Results_list!$C$4,SSP1_Baseline!D:D,Results_list!D13,SSP1_Baseline!B:B,2025))) / (SUMIFS(SSP1_Baseline!E:E,SSP1_Baseline!C:C,Results_list!$C$4,SSP1_Baseline!D:D,Results_list!D13,SSP1_Baseline!B:B,2025)) -> 0.0001834886 | H13: =((SUMIFS(SSP1_VSI!F:F,SSP1_VSI!C:C,Results_list!$C$4,SSP1_VSI!D:D,Results_list!D13,SSP1_VSI!B:B,2040)) - (SUMIFS(SSP1_VSI!F:F,SSP1_VSI!C:C,Results_list!$C$4,SSP1_VSI!D:D,Results_list!D13,SSP1_VSI!B:B,2025))) / (SUMIFS(SSP1_VSI!F:F,SSP1_VSI!C:C,Results_list!$C$4,SSP1_VSI!D:D,Results_list!D13,SSP1_VSI!B:B,2025)) -> 0.00018356159 | I13: =ROUND(H13-G13,2) -> 0 | J13: =((SUMIFS(SSP2_Baseline!$E:$E,SSP2_Baseline!$C:$C,Results_list!$C$4,SSP2_Baseline!$D:$D,Results_list!$D13,SSP2_Baseline!$B:$B,2040)) - (SUMIFS(SSP2_Baseline!$E:$E,SSP2_Baseline!$C:$C,Results_list!$C$4,SSP2_Baseline!$D:$D,Results_list!$D13,SSP2_Baseline!$B:$B,2025))) / (SUMIFS(SSP2_Baseline!$E:$E,SSP2_Baseline!$C:$C,Results_list!$C$4,SSP2_Baseline!$D:$D,Results_list!$D13,SSP2_Baseline!$B:$B,2025)) -> 0.00011073193 | K13: =((SUMIFS(SSP2_VSI!$F:$F,SSP2_VSI!$C:$C,Results_list!$C$4,SSP2_VSI!$D:$D,Results_list!$D13,SSP2_VSI!$B:$B,2040)) - (SUMIFS(SSP2_VSI!$F:$F,SSP2_VSI!$C:$C,Results_list!$C$4,SSP2_VSI!$D:$D,Results_list!$D13,SSP2_VSI!$B:$B,2025))) / (SUMIFS(SSP2_VSI!$F:$F,SSP2_VSI!$C:$C,Results_list!$C$4,SSP2_VSI!$D:$D,Results_list!$D13,SSP2_VSI!$B:$B,2025)) -> 0.00011065093 | L13: =ROUND(K13-J13,2) -> 0 | M13: =((SUMIFS(SSP5_Baseline!$E:$E,SSP5_Baseline!$C:$C,Results_list!$C$4,SSP5_Baseline!$D:$D,Results_list!$D13,SSP5_Baseline!$B:$B,2040)) - (SUMIFS(SSP5_Baseline!$E:$E,SSP5_Baseline!$C:$C,Results_list!$C$4,SSP5_Baseline!$D:$D,Results_list!$D13,SSP5_Baseline!$B:$B,2025))) / (SUMIFS(SSP5_Baseline!$E:$E,SSP5_Baseline!$C:$C,Results_list!$C$4,SSP5_Baseline!$D:$D,Results_list!$D13,SSP5_Baseline!$B:$B,2025)) -> 0.00043000304 | N13: =((SUMIFS(SSP5_VSI!$F:$F,SSP5_VSI!$C:$C,Results_list!$C$4,SSP5_VSI!$D:$D,Results_list!$D13,SSP5_VSI!$B:$B,2040)) - (SUMIFS(SSP5_VSI!$F:$F,SSP5_VSI!$C:$C,Results_list!$C$4,SSP5_VSI!$D:$D,Results_list!$D13,SSP5_VSI!$B:$B,2025))) / (SUMIFS(SSP5_VSI!$F:$F,SSP5_VSI!$C:$C,Results_list!$C$4,SSP5_VSI!$D:$D,Results_list!$D13,SSP5_VSI!$B:$B,2025)) -> 0.0004301234 | O13: =ROUND(N13-M13,2) -> 0
D14: ('ReCiPe Midpoint (H)', 'terrestrial acidification', 'TAP100') | F14: TAP100 | G14: =((SUMIFS(SSP1_Baseline!E:E,SSP1_Baseline!C:C,Results_list!$C$4,SSP1_Baseline!D:D,Results_list!D14,SSP1_Baseline!B:B,2040)) - (SUMIFS(SSP1_Baseline!E:E,SSP1_Baseline!C:C,Results_list!$C$4,SSP1_Baseline!D:D,Results_list!D14,SSP1_Baseline!B:B,2025))) / (SUMIFS(SSP1_Baseline!E:E,SSP1_Baseline!C:C,Results_list!$C$4,SSP1_Baseline!D:D,Results_list!D14,SSP1_Baseline!B:B,2025)) -> -0.001703269 | H14: =((SUMIFS(SSP1_VSI!F:F,SSP1_VSI!C:C,Results_list!$C$4,SSP1_VSI!D:D,Results_list!D14,SSP1_VSI!B:B,2040)) - (SUMIFS(SSP1_VSI!F:F,SSP1_VSI!C:C,Results_list!$C$4,SSP1_VSI!D:D,Results_list!D14,SSP1_VSI!B:B,2025))) / (SUMIFS(SSP1_VSI!F:F,SSP1_VSI!C:C,Results_list!$C$4,SSP1_VSI!D:D,Results_list!D14,SSP1_VSI!B:B,2025)) -> -0.96570456 | I14: =ROUND(H14-G14,2) -> -0.96 | J14: =((SUMIFS(SSP2_Baseline!$E:$E,SSP2_Baseline!$C:$C,Results_list!$C$4,SSP2_Baseline!$D:$D,Results_list!$D14,SSP2_Baseline!$B:$B,2040)) - (SUMIFS(SSP2_Baseline!$E:$E,SSP2_Baseline!$C:$C,Results_list!$C$4,SSP2_Baseline!$D:$D,Results_list!$D14,SSP2_Baseline!$B:$B,2025))) / (SUMIFS(SSP2_Baseline!$E:$E,SSP2_Baseline!$C:$C,Results_list!$C$4,SSP2_Baseline!$D:$D,Results_list!$D14,SSP2_Baseline!$B:$B,2025)) -> -0.0017687554 | K14: =((SUMIFS(SSP2_VSI!$F:$F,SSP2_VSI!$C:$C,Results_list!$C$4,SSP2_VSI!$D:$D,Results_list!$D14,SSP2_VSI!$B:$B,2040)) - (SUMIFS(SSP2_VSI!$F:$F,SSP2_VSI!$C:$C,Results_list!$C$4,SSP2_VSI!$D:$D,Results_list!$D14,SSP2_VSI!$B:$B,2025))) / (SUMIFS(SSP2_VSI!$F:$F,SSP2_VSI!$C:$C,Results_list!$C$4,SSP2_VSI!$D:$D,Results_list!$D14,SSP2_VSI!$B:$B,2025)) -> -0.96597336 | L14: =ROUND(K14-J14,2) -> -0.96 | M14: =((SUMIFS(SSP5_Baseline!$E:$E,SSP5_Baseline!$C:$C,Results_list!$C$4,SSP5_Baseline!$D:$D,Results_list!$D14,SSP5_Baseline!$B:$B,2040)) - (SUMIFS(SSP5_Baseline!$E:$E,SSP5_Baseline!$C:$C,Results_list!$C$4,SSP5_Baseline!$D:$D,Results_list!$D14,SSP5_Baseline!$B:$B,2025))) / (SUMIFS(SSP5_Baseline!$E:$E,SSP5_Baseline!$C:$C,Results_list!$C$4,SSP5_Baseline!$D:$D,Results_list!$D14,SSP5_Baseline!$B:$B,2025)) -> -0.0019166264 | N14: =((SUMIFS(SSP5_VSI!$F:$F,SSP5_VSI!$C:$C,Results_list!$C$4,SSP5_VSI!$D:$D,Results_list!$D14,SSP5_VSI!$B:$B,2040)) - (SUMIFS(SSP5_VSI!$F:$F,SSP5_VSI!$C:$C,Results_list!$C$4,SSP5_VSI!$D:$D,Results_list!$D14,SSP5_VSI!$B:$B,2025))) / (SUMIFS(SSP5_VSI!$F:$F,SSP5_VSI!$C:$C,Results_list!$C$4,SSP5_VSI!$D:$D,Results_list!$D14,SSP5_VSI!$B:$B,2025)) -> -0.96413826 | O14: =ROUND(N14-M14,2) -> -0.96
D15: ('ReCiPe Midpoint (H)', 'water depletion', 'WDP') | F15: WDP | G15: =((SUMIFS(SSP1_Baseline!E:E,SSP1_Baseline!C:C,Results_list!$C$4,SSP1_Baseline!D:D,Results_list!D15,SSP1_Baseline!B:B,2040)) - (SUMIFS(SSP1_Baseline!E:E,SSP1_Baseline!C:C,Results_list!$C$4,SSP1_Baseline!D:D,Results_list!D15,SSP1_Baseline!B:B,2025))) / (SUMIFS(SSP1_Baseline!E:E,SSP1_Baseline!C:C,Results_list!$C$4,SSP1_Baseline!D:D,Results_list!D15,SSP1_Baseline!B:B,2025)) -> -0.019804362 | H15: =((SUMIFS(SSP1_VSI!F:F,SSP1_VSI!C:C,Results_list!$C$4,SSP1_VSI!D:D,Results_list!D15,SSP1_VSI!B:B,2040)) - (SUMIFS(SSP1_VSI!F:F,SSP1_VSI!C:C,Results_list!$C$4,SSP1_VSI!D:D,Results_list!D15,SSP1_VSI!B:B,2025))) / (SUMIFS(SSP1_VSI!F:F,SSP1_VSI!C:C,Results_list!$C$4,SSP1_VSI!D:D,Results_list!D15,SSP1_VSI!B:B,2025)) -> -0.019802941 | I15: =ROUND(H15-G15,2) -> 0 | J15: =((SUMIFS(SSP2_Baseline!$E:$E,SSP2_Baseline!$C:$C,Results_list!$C$4,SSP2_Baseline!$D:$D,Results_list!$D15,SSP2_Baseline!$B:$B,2040)) - (SUMIFS(SSP2_Baseline!$E:$E,SSP2_Baseline!$C:$C,Results_list!$C$4,SSP2_Baseline!$D:$D,Results_list!$D15,SSP2_Baseline!$B:$B,2025))) / (SUMIFS(SSP2_Baseline!$E:$E,SSP2_Baseline!$C:$C,Results_list!$C$4,SSP2_Baseline!$D:$D,Results_list!$D15,SSP2_Baseline!$B:$B,2025)) -> -0.0038794792 | K15: =((SUMIFS(SSP2_VSI!$F:$F,SSP2_VSI!$C:$C,Results_list!$C$4,SSP2_VSI!$D:$D,Results_list!$D15,SSP2_VSI!$B:$B,2040)) - (SUMIFS(SSP2_VSI!$F:$F,SSP2_VSI!$C:$C,Results_list!$C$4,SSP2_VSI!$D:$D,Results_list!$D15,SSP2_VSI!$B:$B,2025))) / (SUMIFS(SSP2_VSI!$F:$F,SSP2_VSI!$C:$C,Results_list!$C$4,SSP2_VSI!$D:$D,Results_list!$D15,SSP2_VSI!$B:$B,2025)) -> -0.0038817102 | L15: =ROUND(K15-J15,2) -> 0 | M15: =((SUMIFS(SSP5_Baseline!$E:$E,SSP5_Baseline!$C:$C,Results_list!$C$4,SSP5_Baseline!$D:$D,Results_list!$D15,SSP5_Baseline!$B:$B,2040)) - (SUMIFS(SSP5_Baseline!$E:$E,SSP5_Baseline!$C:$C,Results_list!$C$4,SSP5_Baseline!$D:$D,Results_list!$D15,SSP5_Baseline!$B:$B,2025))) / (SUMIFS(SSP5_Baseline!$E:$E,SSP5_Baseline!$C:$C,Results_list!$C$4,SSP5_Baseline!$D:$D,Results_list!$D15,SSP5_Baseline!$B:$B,2025)) -> 0.0089564452 | N15: =((SUMIFS(SSP5_VSI!$F:$F,SSP5_VSI!$C:$C,Results_list!$C$4,SSP5_VSI!$D:$D,Results_list!$D15,SSP5_VSI!$B:$B,2040)) - (SUMIFS(SSP5_VSI!$F:$F,SSP5_VSI!$C:$C,Results_list!$C$4,SSP5_VSI!$D:$D,Results_list!$D15,SSP5_VSI!$B:$B,2025))) / (SUMIFS(SSP5_VSI!$F:$F,SSP5_VSI!$C:$C,Results_list!$C$4,SSP5_VSI!$D:$D,Results_list!$D15,SSP5_VSI!$B:$B,2025)) -> 0.0089589037 | O15: =ROUND(N15-M15,2) -> 0
D16: ('ReCiPe Midpoint (H)', 'urban land occupation', 'ULOP') | F16: ULOP | G16: =((SUMIFS(SSP1_Baseline!E:E,SSP1_Baseline!C:C,Results_list!$C$4,SSP1_Baseline!D:D,Results_list!D16,SSP1_Baseline!B:B,2040)) - (SUMIFS(SSP1_Baseline!E:E,SSP1_Baseline!C:C,Results_list!$C$4,SSP1_Baseline!D:D,Results_list!D16,SSP1_Baseline!B:B,2025))) / (SUMIFS(SSP1_Baseline!E:E,SSP1_Baseline!C:C,Results_list!$C$4,SSP1_Baseline!D:D,Results_list!D16,SSP1_Baseline!B:B,2025)) -> -0.010297453 | H16: =((SUMIFS(SSP1_VSI!F:F,SSP1_VSI!C:C,Results_list!$C$4,SSP1_VSI!D:D,Results_list!D16,SSP1_VSI!B:B,2040)) - (SUMIFS(SSP1_VSI!F:F,SSP1_VSI!C:C,Results_list!$C$4,SSP1_VSI!D:D,Results_list!D16,SSP1_VSI!B:B,2025))) / (SUMIFS(SSP1_VSI!F:F,SSP1_VSI!C:C,Results_list!$C$4,SSP1_VSI!D:D,Results_list!D16,SSP1_VSI!B:B,2025)) -> -0.010305499 | I16: =ROUND(H16-G16,2) -> 0 | J16: =((SUMIFS(SSP2_Baseline!$E:$E,SSP2_Baseline!$C:$C,Results_list!$C$4,SSP2_Baseline!$D:$D,Results_list!$D16,SSP2_Baseline!$B:$B,2040)) - (SUMIFS(SSP2_Baseline!$E:$E,SSP2_Baseline!$C:$C,Results_list!$C$4,SSP2_Baseline!$D:$D,Results_list!$D16,SSP2_Baseline!$B:$B,2025))) / (SUMIFS(SSP2_Baseline!$E:$E,SSP2_Baseline!$C:$C,Results_list!$C$4,SSP2_Baseline!$D:$D,Results_list!$D16,SSP2_Baseline!$B:$B,2025)) -> -0.010039134 | K16: =((SUMIFS(SSP2_VSI!$F:$F,SSP2_VSI!$C:$C,Results_list!$C$4,SSP2_VSI!$D:$D,Results_list!$D16,SSP2_VSI!$B:$B,2040)) - (SUMIFS(SSP2_VSI!$F:$F,SSP2_VSI!$C:$C,Results_list!$C$4,SSP2_VSI!$D:$D,Results_list!$D16,SSP2_VSI!$B:$B,2025))) / (SUMIFS(SSP2_VSI!$F:$F,SSP2_VSI!$C:$C,Results_list!$C$4,SSP2_VSI!$D:$D,Results_list!$D16,SSP2_VSI!$B:$B,2025)) -> -0.010196007 | L16: =ROUND(K16-J16,2) -> 0 | M16: =((SUMIFS(SSP5_Baseline!$E:$E,SSP5_Baseline!$C:$C,Results_list!$C$4,SSP5_Baseline!$D:$D,Results_list!$D16,SSP5_Baseline!$B:$B,2040)) - (SUMIFS(SSP5_Baseline!$E:$E,SSP5_Baseline!$C:$C,Results_list!$C$4,SSP5_Baseline!$D:$D,Results_list!$D16,SSP5_Baseline!$B:$B,2025))) / (SUMIFS(SSP5_Baseline!$E:$E,SSP5_Baseline!$C:$C,Results_list!$C$4,SSP5_Baseline!$D:$D,Results_list!$D16,SSP5_Baseline!$B:$B,2025)) -> -0.032423093 | N16: =((SUMIFS(SSP5_VSI!$F:$F,SSP5_VSI!$C:$C,Results_list!$C$4,SSP5_VSI!$D:$D,Results_list!$D16,SSP5_VSI!$B:$B,2040)) - (SUMIFS(SSP5_VSI!$F:$F,SSP5_VSI!$C:$C,Results_list!$C$4,SSP5_VSI!$D:$D,Results_list!$D16,SSP5_VSI!$B:$B,2025))) / (SUMIFS(SSP5_VSI!$F:$F,SSP5_VSI!$C:$C,Results_list!$C$4,SSP5_VSI!$D:$D,Results_list!$D16,SSP5_VSI!$B:$B,2025)) -> -0.032373522 | O16: =ROUND(N16-M16,2) -> 0
... D21: ('ReCiPe Midpoint (H)', 'ozone depletion', 'ODPinf') | F21: ODPinf | G21: =((SUMIFS(SSP1_Baseline!E:E,SSP1_Baseline!C:C,Results_list!$C$4,SSP1_Baseline!D:D,Results_list!D21,SSP1_Baseline!B:B,2040)) - (SUMIFS(SSP1_Baseline!E:E,SSP1_Baseline!C:C,Results_list!$C$4,SSP1_Baseline!D:D,Results_list!D21,SSP1_Baseline!B:B,2025))) / (SUMIFS(SSP1_Baseline!E:E,SSP1_Baseline!C:C,Results_list!$C$4,SSP1_Baseline!D:D,Results_list!D21,SSP1_Baseline!B:B,2025)) -> 0.070987285 | H21: =((SUMIFS(SSP1_VSI!F:F,SSP1_VSI!C:C,Results_list!$C$4,SSP1_VSI!D:D,Results_list!D21,SSP1_VSI!B:B,2040)) - (SUMIFS(SSP1_VSI!F:F,SSP1_VSI!C:C,Results_list!$C$4,SSP1_VSI!D:D,Results_list!D21,SSP1_VSI!B:B,2025))) / (SUMIFS(SSP1_VSI!F:F,SSP1_VSI!C:C,Results_list!$C$4,SSP1_VSI!D:D,Results_list!D21,SSP1_VSI!B:B,2025)) -> 0.071002535 | I21: =ROUND(H21-G21,2) -> 0 | J21: =((SUMIFS(SSP2_Baseline!$E:$E,SSP2_Baseline!$C:$C,Results_list!$C$4,SSP2_Baseline!$D:$D,Results_list!$D21,SSP2_Baseline!$B:$B,2040)) - (SUMIFS(SSP2_Baseline!$E:$E,SSP2_Baseline!$C:$C,Results_list!$C$4,SSP2_Baseline!$D:$D,Results_list!$D21,SSP2_Baseline!$B:$B,2025))) / (SUMIFS(SSP2_Baseline!$E:$E,SSP2_Baseline!$C:$C,Results_list!$C$4,SSP2_Baseline!$D:$D,Results_list!$D21,SSP2_Baseline!$B:$B,2025)) -> 0.076996891 | K21: =((SUMIFS(SSP2_VSI!$F:$F,SSP2_VSI!$C:$C,Results_list!$C$4,SSP2_VSI!$D:$D,Results_list!$D21,SSP2_VSI!$B:$B,2040)) - (SUMIFS(SSP2_VSI!$F:$F,SSP2_VSI!$C:$C,Results_list!$C$4,SSP2_VSI!$D:$D,Results_list!$D21,SSP2_VSI!$B:$B,2025))) / (SUMIFS(SSP2_VSI!$F:$F,SSP2_VSI!$C:$C,Results_list!$C$4,SSP2_VSI!$D:$D,Results_list!$D21,SSP2_VSI!$B:$B,2025)) -> 0.076965899 | L21: =ROUND(K21-J21,2) -> 0 | M21: =((SUMIFS(SSP5_Baseline!$E:$E,SSP5_Baseline!$C:$C,Results_list!$C$4,SSP5_Baseline!$D:$D,Results_list!$D21,SSP5_Baseline!$B:$B,2040)) - (SUMIFS(SSP5_Baseline!$E:$E,SSP5_Baseline!$C:$C,Results_list!$C$4,SSP5_Baseline!$D:$D,Results_list!$D21,SSP5_Baseline!$B:$B,2025))) / (SUMIFS(SSP5_Baseline!$E:$E,SSP5_Baseline!$C:$C,Results_list!$C$4,SSP5_Baseline!$D:$D,Results_list!$D21,SSP5_Baseline!$B:$B,2025)) -> 0.2669958 | N21: =((SUMIFS(SSP5_VSI!$F:$F,SSP5_VSI!$C:$C,Results_list!$C$4,SSP5_VSI!$D:$D,Results_list!$D21,SSP5_VSI!$B:$B,2040)) - (SUMIFS(SSP5_VSI!$F:$F,SSP5_VSI!$C:$C,Results_list!$C$4,SSP5_VSI!$D:$D,Results_list!$D21,SSP5_VSI!$B:$B,2025))) / (SUMIFS(SSP5_VSI!$F:$F,SSP5_VSI!$C:$C,Results_list!$C$4,SSP5_VSI!$D:$D,Results_list!$D21,SSP5_VSI!$B:$B,2025)) -> 0.26705147 | O21: =ROUND(N21-M21,2) -> 0
G23: Scenario
B24: Activity | C24: Activity | D24: Impact Category | F24: Impact Mitigation | G24: SSP1 | H24: SSP1 + VSI | I24: Δ% | J24: SSP2 | K24: SSP2 + VSI | L24: Δ% | M24: SSP5 | N24: SSP5 + VSI | O24: Δ%
B25: platinum group metal, mine and concentration operations (ZA) | C25: platinum group metal, mine and concentration operations | D25: ('ReCiPe Midpoint (H)', 'terrestrial ecotoxicity', 'TETPinf') | F25: TETPinf | G25: =((SUMIFS(SSP1_Baseline!$E:$E,SSP1_Baseline!$C:$C,Results_list!$C$25,SSP1_Baseline!$D:$D,Results_list!$D25,SSP1_Baseline!$B:$B,2040)) - (SUMIFS(SSP1_Baseline!$E:$E,SSP1_Baseline!$C:$C,Results_list!$C$25,SSP1_Baseline!$D:$D,Results_list!$D25,SSP1_Baseline!$B:$B,2025))) / (SUMIFS(SSP1_Baseline!$E:$E,SSP1_Baseline!$C:$C,Results_list!$C$25,SSP1_Baseline!$D:$D,Results_list!$D25,SSP1_Baseline!$B:$B,2025)) -> -0.10860359 | H25: =((SUMIFS(SSP1_VSI!$F:$F,SSP1_VSI!$C:$C,Results_list!$C$25,SSP1_VSI!$D:$D,Results_list!$D25,SSP1_VSI!$B:$B,2040)) - (SUMIFS(SSP1_VSI!$F:$F,SSP1_VSI!$C:$C,Results_list!$C$25,SSP1_VSI!$D:$D,Results_list!$D25,SSP1_VSI!$B:$B,2025))) / (SUMIFS(SSP1_VSI!$F:$F,SSP1_VSI!$C:$C,Results_list!$C$25,SSP1_VSI!$D:$D,Results_list!$D25,SSP1_VSI!$B:$B,2025)) -> -0.13098719 | I25: =ROUND(H25-G25,3) -> -0.022 | J25: =((SUMIFS(SSP2_Baseline!$E:$E,SSP2_Baseline!$C:$C,Results_list!$C$25,SSP2_Baseline!$D:$D,Results_list!$D25,SSP2_Baseline!$B:$B,2040)) - (SUMIFS(SSP2_Baseline!$E:$E,SSP2_Baseline!$C:$C,Results_list!$C$25,SSP2_Baseline!$D:$D,Results_list!$D25,SSP2_Baseline!$B:$B,2025))) / (SUMIFS(SSP2_Baseline!$E:$E,SSP2_Baseline!$C:$C,Results_list!$C$25,SSP2_Baseline!$D:$D,Results_list!$D25,SSP2_Baseline!$B:$B,2025)) -> 0.73496019 | K25: =((SUMIFS(SSP2_VSI!$F:$F,SSP2_VSI!$C:$C,Results_list!$C$25,SSP2_VSI!$D:$D,Results_list!$D25,SSP2_VSI!$B:$B,2040)) - (SUMIFS(SSP2_VSI!$F:$F,SSP2_VSI!$C:$C,Results_list!$C$25,SSP2_VSI!$D:$D,Results_list!$D25,SSP2_VSI!$B:$B,2025))) / (SUMIFS(SSP2_VSI!$F:$F,SSP2_VSI!$C:$C,Results_list!$C$25,SSP2_VSI!$D:$D,Results_list!$D25,SSP2_VSI!$B:$B,2025)) -> 0.65894041 | L25: =ROUND(K25-J25,2) -> -0.08 | M25: =((SUMIFS(SSP5_Baseline!$E:$E,SSP5_Baseline!$C:$C,Results_list!$C$25,SSP5_Baseline!$D:$D,Results_list!$D25,SSP5_Baseline!$B:$B,2040)) - (SUMIFS(SSP5_Baseline!$E:$E,SSP5_Baseline!$C:$C,Results_list!$C$25,SSP5_Baseline!$D:$D,Results_list!$D25,SSP5_Baseline!$B:$B,2025))) / (SUMIFS(SSP5_Baseline!$E:$E,SSP5_Baseline!$C:$C,Results_list!$C$25,SSP5_Baseline!$D:$D,Results_list!$D25,SSP5_Baseline!$B:$B,2025)) -> 1.4199223 | N25: =((SUMIFS(SSP5_VSI!$F:$F,SSP5_VSI!$C:$C,Results_list!$C$25,SSP5_VSI!$D:$D,Results_list!$D25,SSP5_VSI!$B:$B,2040)) - (SUMIFS(SSP5_VSI!$F:$F,SSP5_VSI!$C:$C,Results_list!$C$25,SSP5_VSI!$D:$D,Results_list!$D25,SSP5_VSI!$B:$B,2025))) / (SUMIFS(SSP5_VSI!$F:$F,SSP5_VSI!$C:$C,Results_list!$C$25,SSP5_VSI!$D:$D,Results_list!$D25,SSP5_VSI!$B:$B,2025)) -> 1.3287323 | O25: =ROUND(N25-M25,2) -> -0.09
D26: ('ReCiPe Midpoint (H)', 'natural land transformation', 'NLTP') | F26: NLTP | G26: =((SUMIFS(SSP1_Baseline!$E:$E,SSP1_Baseline!$C:$C,Results_list!$C$25,SSP1_Baseline!$D:$D,Results_list!$D26,SSP1_Baseline!$B:$B,2040)) - (SUMIFS(SSP1_Baseline!$E:$E,SSP1_Baseline!$C:$C,Results_list!$C$25,SSP1_Baseline!$D:$D,Results_list!$D26,SSP1_Baseline!$B:$B,2025))) / (SUMIFS(SSP1_Baseline!$E:$E,SSP1_Baseline!$C:$C,Results_list!$C$25,SSP1_Baseline!$D:$D,Results_list!$D26,SSP1_Baseline!$B:$B,2025)) -> -0.0047633201 | H26: =((SUMIFS(SSP1_VSI!$F:$F,SSP1_VSI!$C:$C,Results_list!$C$25,SSP1_VSI!$D:$D,Results_list!$D26,SSP1_VSI!$B:$B,2040)) - (SUMIFS(SSP1_VSI!$F:$F,SSP1_VSI!$C:$C,Results_list!$C$25,SSP1_VSI!$D:$D,Results_list!$D26,SSP1_VSI!$B:$B,2025))) / (SUMIFS(SSP1_VSI!$F:$F,SSP1_VSI!$C:$C,Results_list!$C$25,SSP1_VSI!$D:$D,Results_list!$D26,SSP1_VSI!$B:$B,2025)) -> -0.0047639341 | I26: =ROUND(H26-G26,3) -> 0 | J26: =((SUMIFS(SSP2_Baseline!$E:$E,SSP2_Baseline!$C:$C,Results_list!$C$25,SSP2_Baseline!$D:$D,Results_list!$D26,SSP2_Baseline!$B:$B,2040)) - (SUMIFS(SSP2_Baseline!$E:$E,SSP2_Baseline!$C:$C,Results_list!$C$25,SSP2_Baseline!$D:$D,Results_list!$D26,SSP2_Baseline!$B:$B,2025))) / (SUMIFS(SSP2_Baseline!$E:$E,SSP2_Baseline!$C:$C,Results_list!$C$25,SSP2_Baseline!$D:$D,Results_list!$D26,SSP2_Baseline!$B:$B,2025)) -> -0.0080161815 | K26: =((SUMIFS(SSP2_VSI!$F:$F,SSP2_VSI!$C:$C,Results_list!$C$25,SSP2_VSI!$D:$D,Results_list!$D26,SSP2_VSI!$B:$B,2040)) - (SUMIFS(SSP2_VSI!$F:$F,SSP2_VSI!$C:$C,Results_list!$C$25,SSP2_VSI!$D:$D,Results_list!$D26,SSP2_VSI!$B:$B,2025))) / (SUMIFS(SSP2_VSI!$F:$F,SSP2_VSI!$C:$C,Results_list!$C$25,SSP2_VSI!$D:$D,Results_list!$D26,SSP2_VSI!$B:$B,2025)) -> -0.0080174421 | L26: =ROUND(K26-J26,2) -> 0 | M26: =((SUMIFS(SSP5_Baseline!$E:$E,SSP5_Baseline!$C:$C,Results_list!$C$25,SSP5_Baseline!$D:$D,Results_list!$D26,SSP5_Baseline!$B:$B,2040)) - (SUMIFS(SSP5_Baseline!$E:$E,SSP5_Baseline!$C:$C,Results_list!$C$25,SSP5_Baseline!$D:$D,Results_list!$D26,SSP5_Baseline!$B:$B,2025))) / (SUMIFS(SSP5_Baseline!$E:$E,SSP5_Baseline!$C:$C,Results_list!$C$25,SSP5_Baseline!$D:$D,Results_list!$D26,SSP5_Baseline!$B:$B,2025)) -> 0.023752316 | N26: =((SUMIFS(SSP5_VSI!$F:$F,SSP5_VSI!$C:$C,Results_list!$C$25,SSP5_VSI!$D:$D,Results_list!$D26,SSP5_VSI!$B:$B,2040)) - (SUMIFS(SSP5_VSI!$F:$F,SSP5_VSI!$C:$C,Results_list!$C$25,SSP5_VSI!$D:$D,Results_list!$D26,SSP5_VSI!$B:$B,2025))) / (SUMIFS(SSP5_VSI!$F:$F,SSP5_VSI!$C:$C,Results_list!$C$25,SSP5_VSI!$D:$D,Results_list!$D26,SSP5_VSI!$B:$B,2025)) -> 0.023750762 | O26: =ROUND(N26-M26,2) -> 0
D27: ('ReCiPe Midpoint (H)', 'photochemical oxidant formation', 'POFP') | F27: POFP | G27: =((SUMIFS(SSP1_Baseline!$E:$E,SSP1_Baseline!$C:$C,Results_list!$C$25,SSP1_Baseline!$D:$D,Results_list!$D27,SSP1_Baseline!$B:$B,2040)) - (SUMIFS(SSP1_Baseline!$E:$E,SSP1_Baseline!$C:$C,Results_list!$C$25,SSP1_Baseline!$D:$D,Results_list!$D27,SSP1_Baseline!$B:$B,2025))) / (SUMIFS(SSP1_Baseline!$E:$E,SSP1_Baseline!$C:$C,Results_list!$C$25,SSP1_Baseline!$D:$D,Results_list!$D27,SSP1_Baseline!$B:$B,2025)) -> -0.024683329 | H27: =((SUMIFS(SSP1_VSI!$F:$F,SSP1_VSI!$C:$C,Results_list!$C$25,SSP1_VSI!$D:$D,Results_list!$D27,SSP1_VSI!$B:$B,2040)) - (SUMIFS(SSP1_VSI!$F:$F,SSP1_VSI!$C:$C,Results_list!$C$25,SSP1_VSI!$D:$D,Results_list!$D27,SSP1_VSI!$B:$B,2025))) / (SUMIFS(SSP1_VSI!$F:$F,SSP1_VSI!$C:$C,Results_list!$C$25,SSP1_VSI!$D:$D,Results_list!$D27,SSP1_VSI!$B:$B,2025)) -> -0.045218979 | I27: =ROUND(H27-G27,3) -> -0.021 | J27: =((SUMIFS(SSP2_Baseline!$E:$E,SSP2_Baseline!$C:$C,Results_list!$C$25,SSP2_Baseline!$D:$D,Results_list!$D27,SSP2_Baseline!$B:$B,2040)) - (SUMIFS(SSP2_Baseline!$E:$E,SSP2_Baseline!$C:$C,Results_list!$C$25,SSP2_Baseline!$D:$D,Results_list!$D27,SSP2_Baseline!$B:$B,2025))) / (SUMIFS(SSP2_Baseline!$E:$E,SSP2_Baseline!$C:$C,Results_list!$C$25,SSP2_Baseline!$D:$D,Results_list!$D27,SSP2_Baseline!$B:$B,2025)) -> -0.024416096 | K27: =((SUMIFS(SSP2_VSI!$F:$F,SSP2_VSI!$C:$C,Results_list!$C$25,SSP2_VSI!$D:$D,Results_list!$D27,SSP2_VSI!$B:$B,2040)) - (SUMIFS(SSP2_VSI!$F:$F,SSP2_VSI!$C:$C,Results_list!$C$25,SSP2_VSI!$D:$D,Results_list!$D27,SSP2_VSI!$B:$B,2025))) / (SUMIFS(SSP2_VSI!$F:$F,SSP2_VSI!$C:$C,Results_list!$C$25,SSP2_VSI!$D:$D,Results_list!$D27,SSP2_VSI!$B:$B,2025)) -> -0.044982421 | L27: =ROUND(K27-J27,2) -> -0.02 | M27: =((SUMIFS(SSP5_Baseline!$E:$E,SSP5_Baseline!$C:$C,Results_list!$C$25,SSP5_Baseline!$D:$D,Results_list!$D27,SSP5_Baseline!$B:$B,2040)) - (SUMIFS(SSP5_Baseline!$E:$E,SSP5_Baseline!$C:$C,Results_list!$C$25,SSP5_Baseline!$D:$D,Results_list!$D27,SSP5_Baseline!$B:$B,2025))) / (SUMIFS(SSP5_Baseline!$E:$E,SSP5_Baseline!$C:$C,Results_list!$C$25,SSP5_Baseline!$D:$D,Results_list!$D27,SSP5_Baseline!$B:$B,2025)) -> -0.013432869 | N27: =((SUMIFS(SSP5_VSI!$F:$F,SSP5_VSI!$C:$C,Results_list!$C$25,SSP5_VSI!$D:$D,Results_list!$D27,SSP5_VSI!$B:$B,2040)) - (SUMIFS(SSP5_VSI!$F:$F,SSP5_VSI!$C:$C,Results_list!$C$25,SSP5_VSI!$D:$D,Results_list!$D27,SSP5_VSI!$B:$B,2025))) / (SUMIFS(SSP5_VSI!$F:$F,SSP5_VSI!$C:$C,Results_list!$C$25,SSP5_VSI!$D:$D,Results_list!$D27,SSP5_VSI!$B:$B,2025)) -> -0.033945285 | O27: =ROUND(N27-M27,2) -> -0.02
D28: ('ReCiPe Midpoint (H)', 'human toxicity', 'HTPinf') | F28: HTPinf | G28: =((SUMIFS(SSP1_Baseline!$E:$E,SSP1_Baseline!$C:$C,Results_list!$C$25,SSP1_Baseline!$D:$D,Results_list!$D28,SSP1_Baseline!$B:$B,2040)) - (SUMIFS(SSP1_Baseline!$E:$E,SSP1_Baseline!$C:$C,Results_list!$C$25,SSP1_Baseline!$D:$D,Results_list!$D28,SSP1_Baseline!$B:$B,2025))) / (SUMIFS(SSP1_Baseline!$E:$E,SSP1_Baseline!$C:$C,Results_list!$C$25,SSP1_Baseline!$D:$D,Results_list!$D28,SSP1_Baseline!$B:$B,2025)) -> -0.014180316 | H28: =((SUMIFS(SSP1_VSI!$F:$F,SSP1_VSI!$C:$C,Results_list!$C$25,SSP1_VSI!$D:$D,Results_list!$D28,SSP1_VSI!$B:$B,2040)) - (SUMIFS(SSP1_VSI!$F:$F,SSP1_VSI!$C:$C,Results_list!$C$25,SSP1_VSI!$D:$D,Results_list!$D28,SSP1_VSI!$B:$B,2025))) / (SUMIFS(SSP1_VSI!$F:$F,SSP1_VSI!$C:$C,Results_list!$C$25,SSP1_VSI!$D:$D,Results_list!$D28,SSP1_VSI!$B:$B,2025)) -> -0.014728101 | I28: =ROUND(H28-G28,3) -> -0.001 | J28: =((SUMIFS(SSP2_Baseline!$E:$E,SSP2_Baseline!$C:$C,Results_list!$C$25,SSP2_Baseline!$D:$D,Results_list!$D28,SSP2_Baseline!$B:$B,2040)) - (SUMIFS(SSP2_Baseline!$E:$E,SSP2_Baseline!$C:$C,Results_list!$C$25,SSP2_Baseline!$D:$D,Results_list!$D28,SSP2_Baseline!$B:$B,2025))) / (SUMIFS(SSP2_Baseline!$E:$E,SSP2_Baseline!$C:$C,Results_list!$C$25,SSP2_Baseline!$D:$D,Results_list!$D28,SSP2_Baseline!$B:$B,2025)) -> -0.012475177 | K28: =((SUMIFS(SSP2_VSI!$F:$F,SSP2_VSI!$C:$C,Results_list!$C$25,SSP2_VSI!$D:$D,Results_list!$D28,SSP2_VSI!$B:$B,2040)) - (SUMIFS(SSP2_VSI!$F:$F,SSP2_VSI!$C:$C,Results_list!$C$25,SSP2_VSI!$D:$D,Results_list!$D28,SSP2_VSI!$B:$B,2025))) / (SUMIFS(SSP2_VSI!$F:$F,SSP2_VSI!$C:$C,Results_list!$C$25,SSP2_VSI!$D:$D,Results_list!$D28,SSP2_VSI!$B:$B,2025)) -> -0.013024051 | L28: =ROUND(K28-J28,2) -> 0 | M28: =((SUMIFS(SSP5_Baseline!$E:$E,SSP5_Baseline!$C:$C,Results_list!$C$25,SSP5_Baseline!$D:$D,Results_list!$D28,SSP5_Baseline!$B:$B,2040)) - (SUMIFS(SSP5_Baseline!$E:$E,SSP5_Baseline!$C:$C,Results_list!$C$25,SSP5_Baseline!$D:$D,Results_list!$D28,SSP5_Baseline!$B:$B,2025))) / (SUMIFS(SSP5_Baseline!$E:$E,SSP5_Baseline!$C:$C,Results_list!$C$25,SSP5_Baseline!$D:$D,Results_list!$D28,SSP5_Baseline!$B:$B,2025)) -> -0.010964581 | N28: =((SUMIFS(SSP5_VSI!$F:$F,SSP5_VSI!$C:$C,Results_list!$C$25,SSP5_VSI!$D:$D,Results_list!$D28,SSP5_VSI!$B:$B,2040)) - (SUMIFS(SSP5_VSI!$F:$F,SSP5_VSI!$C:$C,Results_list!$C$25,SSP5_VSI!$D:$D,Results_list!$D28,SSP5_VSI!$B:$B,2025))) / (SUMIFS(SSP5_VSI!$F:$F,SSP5_VSI!$C:$C,Results_list!$C$25,SSP5_VSI!$D:$D,Results_list!$D28,SSP5_VSI!$B:$B,2025)) -> -0.01151249 | O28: =ROUND(N28-M28,2) -> 0
D29: ('ReCiPe Midpoint (H)', 'marine eutrophication', 'MEP') | F29: MEP | G29: =((SUMIFS(SSP1_Baseline!$E:$E,SSP1_Baseline!$C:$C,Results_list!$C$25,SSP1_Baseline!$D:$D,Results_list!$D29,SSP1_Baseline!$B:$B,2040)) - (SUMIFS(SSP1_Baseline!$E:$E,SSP1_Baseline!$C:$C,Results_list!$C$25,SSP1_Baseline!$D:$D,Results_list!$D29,SSP1_Baseline!$B:$B,2025))) / (SUMIFS(SSP1_Baseline!$E:$E,SSP1_Baseline!$C:$C,Results_list!$C$25,SSP1_Baseline!$D:$D,Results_list!$D29,SSP1_Baseline!$B:$B,2025)) -> -0.027817945 | H29: =((SUMIFS(SSP1_VSI!$F:$F,SSP1_VSI!$C:$C,Results_list!$C$25,SSP1_VSI!$D:$D,Results_list!$D29,SSP1_VSI!$B:$B,2040)) - (SUMIFS(SSP1_VSI!$F:$F,SSP1_VSI!$C:$C,Results_list!$C$25,SSP1_VSI!$D:$D,Results_list!$D29,SSP1_VSI!$B:$B,2025))) / (SUMIFS(SSP1_VSI!$F:$F,SSP1_VSI!$C:$C,Results_list!$C$25,SSP1_VSI!$D:$D,Results_list!$D29,SSP1_VSI!$B:$B,2025)) -> -0.027824782 | I29: =ROUND(H29-G29,3) -> 0 | J29: =((SUMIFS(SSP2_Baseline!$E:$E,SSP2_Baseline!$C:$C,Results_list!$C$25,SSP2_Baseline!$D:$D,Results_list!$D29,SSP2_Baseline!$B:$B,2040)) - (SUMIFS(SSP2_Baseline!$E:$E,SSP2_Baseline!$C:$C,Results_list!$C$25,SSP2_Baseline!$D:$D,Results_list!$D29,SSP2_Baseline!$B:$B,2025))) / (SUMIFS(SSP2_Baseline!$E:$E,SSP2_Baseline!$C:$C,Results_list!$C$25,SSP2_Baseline!$D:$D,Results_list!$D29,SSP2_Baseline!$B:$B,2025)) -> -0.022394488 | K29: =((SUMIFS(SSP2_VSI!$F:$F,SSP2_VSI!$C:$C,Results_list!$C$25,SSP2_VSI!$D:$D,Results_list!$D29,SSP2_VSI!$B:$B,2040)) - (SUMIFS(SSP2_VSI!$F:$F,SSP2_VSI!$C:$C,Results_list!$C$25,SSP2_VSI!$D:$D,Results_list!$D29,SSP2_VSI!$B:$B,2025))) / (SUMIFS(SSP2_VSI!$F:$F,SSP2_VSI!$C:$C,Results_list!$C$25,SSP2_VSI!$D:$D,Results_list!$D29,SSP2_VSI!$B:$B,2025)) -> -0.022399742 | L29: =ROUND(K29-J29,2) -> 0 | M29: =((SUMIFS(SSP5_Baseline!$E:$E,SSP5_Baseline!$C:$C,Results_list!$C$25,SSP5_Baseline!$D:$D,Results_list!$D29,SSP5_Baseline!$B:$B,2040)) - (SUMIFS(SSP5_Baseline!$E:$E,SSP5_Baseline!$C:$C,Results_list!$C$25,SSP5_Baseline!$D:$D,Results_list!$D29,SSP5_Baseline!$B:$B,2025))) / (SUMIFS(SSP5_Baseline!$E:$E,SSP5_Baseline!$C:$C,Results_list!$C$25,SSP5_Baseline!$D:$D,Results_list!$D29,SSP5_Baseline!$B:$B,2025)) -> -0.017013334 | N29: =((SUMIFS(SSP5_VSI!$F:$F,SSP5_VSI!$C:$C,Results_list!$C$25,SSP5_VSI!$D:$D,Results_list!$D29,SSP5_VSI!$B:$B,2040)) - (SUMIFS(SSP5_VSI!$F:$F,SSP5_VSI!$C:$C,Results_list!$C$25,SSP5_VSI!$D:$D,Results_list!$D29,SSP5_VSI!$B:$B,2025))) / (SUMIFS(SSP5_VSI!$F:$F,SSP5_VSI!$C:$C,Results_list!$C$25,SSP5_VSI!$D:$D,Results_list!$D29,SSP5_VSI!$B:$B,2025)) -> -0.017019455 | O29: =ROUND(N29-M29,2) -> 0
D30: ('IPCC 2013', 'climate change', 'GWP 100a, incl. H and bio CO2') | F30: GWP100 | G30: =((SUMIFS(SSP1_Baseline!$E:$E,SSP1_Baseline!$C:$C,Results_list!$C$25,SSP1_Baseline!$D:$D,Results_list!$D30,SSP1_Baseline!$B:$B,2040)) - (SUMIFS(SSP1_Baseline!$E:$E,SSP1_Baseline!$C:$C,Results_list!$C$25,SSP1_Baseline!$D:$D,Results_list!$D30,SSP1_Baseline!$B:$B,2025))) / (SUMIFS(SSP1_Baseline!$E:$E,SSP1_Baseline!$C:$C,Results_list!$C$25,SSP1_Baseline!$D:$D,Results_list!$D30,SSP1_Baseline!$B:$B,2025)) -> -0.33486602 | H30: =((SUMIFS(SSP1_VSI!$F:$F,SSP1_VSI!$C:$C,Results_list!$C$25,SSP1_VSI!$D:$D,Results_list!$D30,SSP1_VSI!$B:$B,2040)) - (SUMIFS(SSP1_VSI!$F:$F,SSP1_VSI!$C:$C,Results_list!$C$25,SSP1_VSI!$D:$D,Results_list!$D30,SSP1_VSI!$B:$B,2025))) / (SUMIFS(SSP1_VSI!$F:$F,SSP1_VSI!$C:$C,Results_list!$C$25,SSP1_VSI!$D:$D,Results_list!$D30,SSP1_VSI!$B:$B,2025)) -> -0.33499478 | I30: =ROUND(H30-G30,3) -> 0 | J30: =((SUMIFS(SSP2_Baseline!$E:$E,SSP2_Baseline!$C:$C,Results_list!$C$25,SSP2_Baseline!$D:$D,Results_list!$D30,SSP2_Baseline!$B:$B,2040)) - (SUMIFS(SSP2_Baseline!$E:$E,SSP2_Baseline!$C:$C,Results_list!$C$25,SSP2_Baseline!$D:$D,Results_list!$D30,SSP2_Baseline!$B:$B,2025))) / (SUMIFS(SSP2_Baseline!$E:$E,SSP2_Baseline!$C:$C,Results_list!$C$25,SSP2_Baseline!$D:$D,Results_list!$D30,SSP2_Baseline!$B:$B,2025)) -> -0.31165002 | K30: =((SUMIFS(SSP2_VSI!$F:$F,SSP2_VSI!$C:$C,Results_list!$C$25,SSP2_VSI!$D:$D,Results_list!$D30,SSP2_VSI!$B:$B,2040)) - (SUMIFS(SSP2_VSI!$F:$F,SSP2_VSI!$C:$C,Results_list!$C$25,SSP2_VSI!$D:$D,Results_list!$D30,SSP2_VSI!$B:$B,2025))) / (SUMIFS(SSP2_VSI!$F:$F,SSP2_VSI!$C:$C,Results_list!$C$25,SSP2_VSI!$D:$D,Results_list!$D30,SSP2_VSI!$B:$B,2025)) -> -0.31175942 | L30: =ROUND(K30-J30,2) -> 0 | M30: =((SUMIFS(SSP5_Baseline!$E:$E,SSP5_Baseline!$C:$C,Results_list!$C$25,SSP5_Baseline!$D:$D,Results_list!$D30,SSP5_Baseline!$B:$B,2040)) - (SUMIFS(SSP5_Baseline!$E:$E,SSP5_Baseline!$C:$C,Results_list!$C$25,SSP5_Baseline!$D:$D,Results_list!$D30,SSP5_Baseline!$B:$B,2025))) / (SUMIFS(SSP5_Baseline!$E:$E,SSP5_Baseline!$C:$C,Results_list!$C$25,SSP5_Baseline!$D:$D,Results_list!$D30,SSP5_Baseline!$B:$B,2025)) -> -0.16350758 | N30: =((SUMIFS(SSP5_VSI!$F:$F,SSP5_VSI!$C:$C,Results_list!$C$25,SSP5_VSI!$D:$D,Results_list!$D30,SSP5_VSI!$B:$B,2040)) - (SUMIFS(SSP5_VSI!$F:$F,SSP5_VSI!$C:$C,Results_list!$C$25,SSP5_VSI!$D:$D,Results_list!$D30,SSP5_VSI!$B:$B,2025))) / (SUMIFS(SSP5_VSI!$F:$F,SSP5_VSI!$C:$C,Results_list!$C$25,SSP5_VSI!$D:$D,Results_list!$D30,SSP5_VSI!$B:$B,2025)) -> -0.1636031 | O30: =ROUND(N30-M30,2) -> 0
D31: ('ReCiPe Midpoint (H)', 'particulate matter formation', 'PMFP') | F31: PMFP | G31: =((SUMIFS(SSP1_Baseline!$E:$E,SSP1_Baseline!$C:$C,Results_list!$C$25,SSP1_Baseline!$D:$D,Results_list!$D31,SSP1_Baseline!$B:$B,2040)) - (SUMIFS(SSP1_Baseline!$E:$E,SSP1_Baseline!$C:$C,Results_list!$C$25,SSP1_Baseline!$D:$D,Results_list!$D31,SSP1_Baseline!$B:$B,2025))) / (SUMIFS(SSP1_Baseline!$E:$E,SSP1_Baseline!$C:$C,Results_list!$C$25,SSP1_Baseline!$D:$D,Results_list!$D31,SSP1_Baseline!$B:$B,2025)) -> -0.063002353 | H31: =((SUMIFS(SSP1_VSI!$F:$F,SSP1_VSI!$C:$C,Results_list!$C$25,SSP1_VSI!$D:$D,Results_list!$D31,SSP1_VSI!$B:$B,2040)) - (SUMIFS(SSP1_VSI!$F:$F,SSP1_VSI!$C:$C,Results_list!$C$25,SSP1_VSI!$D:$D,Results_list!$D31,SSP1_VSI!$B:$B,2025))) / (SUMIFS(SSP1_VSI!$F:$F,SSP1_VSI!$C:$C,Results_list!$C$25,SSP1_VSI!$D:$D,Results_list!$D31,SSP1_VSI!$B:$B,2025)) -> -0.22264269 | I31: =ROUND(H31-G31,3) -> -0.16 | J31: =((SUMIFS(SSP2_Baseline!$E:$E,SSP2_Baseline!$C:$C,Results_list!$C$25,SSP2_Baseline!$D:$D,Results_list!$D31,SSP2_Baseline!$B:$B,2040)) - (SUMIFS(SSP2_Baseline!$E:$E,SSP2_Baseline!$C:$C,Results_list!$C$25,SSP2_Baseline!$D:$D,Results_list!$D31,SSP2_Baseline!$B:$B,2025))) / (SUMIFS(SSP2_Baseline!$E:$E,SSP2_Baseline!$C:$C,Results_list!$C$25,SSP2_Baseline!$D:$D,Results_list!$D31,SSP2_Baseline!$B:$B,2025)) -> -0.059129563 | K31: =((SUMIFS(SSP2_VSI!$F:$F,SSP2_VSI!$C:$C,Results_list!$C$25,SSP2_VSI!$D:$D,Results_list!$D31,SSP2_VSI!$B:$B,2040)) - (SUMIFS(SSP2_VSI!$F:$F,SSP2_VSI!$C:$C,Results_list!$C$25,SSP2_VSI!$D:$D,Results_list!$D31,SSP2_VSI!$B:$B,2025))) / (SUMIFS(SSP2_VSI!$F:$F,SSP2_VSI!$C:$C,Results_list!$C$25,SSP2_VSI!$D:$D,Results_list!$D31,SSP2_VSI!$B:$B,2025)) -> -0.21964499 | L31: =ROUND(K31-J31,2) -> -0.16 | M31: =((SUMIFS(SSP5_Baseline!$E:$E,SSP5_Baseline!$C:$C,Results_list!$C$25,SSP5_Baseline!$D:$D,Results_list!$D31,SSP5_Baseline!$B:$B,2040)) - (SUMIFS(SSP5_Baseline!$E:$E,SSP5_Baseline!$C:$C,Results_list!$C$25,SSP5_Baseline!$D:$D,Results_list!$D31,SSP5_Baseline!$B:$B,2025))) / (SUMIFS(SSP5_Baseline!$E:$E,SSP5_Baseline!$C:$C,Results_list!$C$25,SSP5_Baseline!$D:$D,Results_list!$D31,SSP5_Baseline!$B:$B,2025)) -> -0.052778219 | N31: =((SUMIFS(SSP5_VSI!$F:$F,SSP5_VSI!$C:$C,Results_list!$C$25,SSP5_VSI!$D:$D,Results_list!$D31,SSP5_VSI!$B:$B,2040)) - (SUMIFS(SSP5_VSI!$F:$F,SSP5_VSI!$C:$C,Results_list!$C$25,SSP5_VSI!$D:$D,Results_list!$D31,SSP5_VSI!$B:$B,2025))) / (SUMIFS(SSP5_VSI!$F:$F,SSP5_VSI!$C:$C,Results_list!$C$25,SSP5_VSI!$D:$D,Results_list!$D31,SSP5_VSI!$B:$B,2025)) -> -0.21435442 | O31: =ROUND(N31-M31,2) -> -0.16
D32: ('ReCiPe Midpoint (H)', 'agricultural land occupation', 'ALOP') | F32: ALOP | G32: =((SUMIFS(SSP1_Baseline!$E:$E,SSP1_Baseline!$C:$C,Results_list!$C$25,SSP1_Baseline!$D:$D,Results_list!$D32,SSP1_Baseline!$B:$B,2040)) - (SUMIFS(SSP1_Baseline!$E:$E,SSP1_Baseline!$C:$C,Results_list!$C$25,SSP1_Baseline!$D:$D,Results_list!$D32,SSP1_Baseline!$B:$B,2025))) / (SUMIFS(SSP1_Baseline!$E:$E,SSP1_Baseline!$C:$C,Results_list!$C$25,SSP1_Baseline!$D:$D,Results_list!$D32,SSP1_Baseline!$B:$B,2025)) -> 0.95369198 | H32: =((SUMIFS(SSP1_VSI!$F:$F,SSP1_VSI!$C:$C,Results_list!$C$25,SSP1_VSI!$D:$D,Results_list!$D32,SSP1_VSI!$B:$B,2040)) - (SUMIFS(SSP1_VSI!$F:$F,SSP1_VSI!$C:$C,Results_list!$C$25,SSP1_VSI!$D:$D,Results_list!$D32,SSP1_VSI!$B:$B,2025))) / (SUMIFS(SSP1_VSI!$F:$F,SSP1_VSI!$C:$C,Results_list!$C$25,SSP1_VSI!$D:$D,Results_list!$D32,SSP1_VSI!$B:$B,2025)) -> 0.95369771 | I32: =ROUND(H32-G32,3) -> 0 | J32: =((SUMIFS(SSP2_Baseline!$E:$E,SSP2_Baseline!$C:$C,Results_list!$C$25,SSP2_Baseline!$D:$D,Results_list!$D32,SSP2_Baseline!$B:$B,2040)) - (SUMIFS(SSP2_Baseline!$E:$E,SSP2_Baseline!$C:$C,Results_list!$C$25,SSP2_Baseline!$D:$D,Results_list!$D32,SSP2_Baseline!$B:$B,2025))) / (SUMIFS(SSP2_Baseline!$E:$E,SSP2_Baseline!$C:$C,Results_list!$C$25,SSP2_Baseline!$D:$D,Results_list!$D32,SSP2_Baseline!$B:$B,2025)) -> 1.0588502 | K32: =((SUMIFS(SSP2_VSI!$F:$F,SSP2_VSI!$C:$C,Results_list!$C$25,SSP2_VSI!$D:$D,Results_list!$D32,SSP2_VSI!$B:$B,2040)) - (SUMIFS(SSP2_VSI!$F:$F,SSP2_VSI!$C:$C,Results_list!$C$25,SSP2_VSI!$D:$D,Results_list!$D32,SSP2_VSI!$B:$B,2025))) / (SUMIFS(SSP2_VSI!$F:$F,SSP2_VSI!$C:$C,Results_list!$C$25,SSP2_VSI!$D:$D,Results_list!$D32,SSP2_VSI!$B:$B,2025)) -> 1.0587797 | L32: =ROUND(K32-J32,2) -> 0 | M32: =((SUMIFS(SSP5_Baseline!$E:$E,SSP5_Baseline!$C:$C,Results_list!$C$25,SSP5_Baseline!$D:$D,Results_list!$D32,SSP5_Baseline!$B:$B,2040)) - (SUMIFS(SSP5_Baseline!$E:$E,SSP5_Baseline!$C:$C,Results_list!$C$25,SSP5_Baseline!$D:$D,Results_list!$D32,SSP5_Baseline!$B:$B,2025))) / (SUMIFS(SSP5_Baseline!$E:$E,SSP5_Baseline!$C:$C,Results_list!$C$25,SSP5_Baseline!$D:$D,Results_list!$D32,SSP5_Baseline!$B:$B,2025)) -> 0.78717594 | N32: =((SUMIFS(SSP5_VSI!$F:$F,SSP5_VSI!$C:$C,Results_list!$C$25,SSP5_VSI!$D:$D,Results_list!$D32,SSP5_VSI!$B:$B,2040)) - (SUMIFS(SSP5_VSI!$F:$F,SSP5_VSI!$C:$C,Results_list!$C$25,SSP5_VSI!$D:$D,Results_list!$D32,SSP5_VSI!$B:$B,2025))) / (SUMIFS(SSP5_VSI!$F:$F,SSP5_VSI!$C:$C,Results_list!$C$25,SSP5_VSI!$D:$D,Results_list!$D32,SSP5_VSI!$B:$B,2025)) -> 0.78718275 | O32: =ROUND(N32-M32,2) -> 0
D33: ('ReCiPe Midpoint (H)', 'freshwater eutrophication', 'FEP') | F33: FEP | G33: =((SUMIFS(SSP1_Baseline!$E:$E,SSP1_Baseline!$C:$C,Results_list!$C$25,SSP1_Baseline!$D:$D,Results_list!$D33,SSP1_Baseline!$B:$B,2040)) - (SUMIFS(SSP1_Baseline!$E:$E,SSP1_Baseline!$C:$C,Results_list!$C$25,SSP1_Baseline!$D:$D,Results_list!$D33,SSP1_Baseline!$B:$B,2025))) / (SUMIFS(SSP1_Baseline!$E:$E,SSP1_Baseline!$C:$C,Results_list!$C$25,SSP1_Baseline!$D:$D,Results_list!$D33,SSP1_Baseline!$B:$B,2025)) -> -0.084458413 | H33: =((SUMIFS(SSP1_VSI!$F:$F,SSP1_VSI!$C:$C,Results_list!$C$25,SSP1_VSI!$D:$D,Results_list!$D33,SSP1_VSI!$B:$B,2040)) - (SUMIFS(SSP1_VSI!$F:$F,SSP1_VSI!$C:$C,Results_list!$C$25,SSP1_VSI!$D:$D,Results_list!$D33,SSP1_VSI!$B:$B,2025))) / (SUMIFS(SSP1_VSI!$F:$F,SSP1_VSI!$C:$C,Results_list!$C$25,SSP1_VSI!$D:$D,Results_list!$D33,SSP1_VSI!$B:$B,2025)) -> -0.084454944 | I33: =ROUND(H33-G33,3) -> 0 | J33: =((SUMIFS(SSP2_Baseline!$E:$E,SSP2_Baseline!$C:$C,Results_list!$C$25,SSP2_Baseline!$D:$D,Results_list!$D33,SSP2_Baseline!$B:$B,2040)) - (SUMIFS(SSP2_Baseline!$E:$E,SSP2_Baseline!$C:$C,Results_list!$C$25,SSP2_Baseline!$D:$D,Results_list!$D33,SSP2_Baseline!$B:$B,2025))) / (SUMIFS(SSP2_Baseline!$E:$E,SSP2_Baseline!$C:$C,Results_list!$C$25,SSP2_Baseline!$D:$D,Results_list!$D33,SSP2_Baseline!$B:$B,2025)) -> -0.074806431 | K33: =((SUMIFS(SSP2_VSI!$F:$F,SSP2_VSI!$C:$C,Results_list!$C$25,SSP2_VSI!$D:$D,Results_list!$D33,SSP2_VSI!$B:$B,2040)) - (SUMIFS(SSP2_VSI!$F:$F,SSP2_VSI!$C:$C,Results_list!$C$25,SSP2_VSI!$D:$D,Results_list!$D33,SSP2_VSI!$B:$B,2025))) / (SUMIFS(SSP2_VSI!$F:$F,SSP2_VSI!$C:$C,Results_list!$C$25,SSP2_VSI!$D:$D,Results_list!$D33,SSP2_VSI!$B:$B,2025)) -> -0.074805326 | L33: =ROUND(K33-J33,2) -> 0 | M33: =((SUMIFS(SSP5_Baseline!$E:$E,SSP5_Baseline!$C:$C,Results_list!$C$25,SSP5_Baseline!$D:$D,Results_list!$D33,SSP5_Baseline!$B:$B,2040)) - (SUMIFS(SSP5_Baseline!$E:$E,SSP5_Baseline!$C:$C,Results_list!$C$25,SSP5_Baseline!$D:$D,Results_list!$D33,SSP5_Baseline!$B:$B,2025))) / (SUMIFS(SSP5_Baseline!$E:$E,SSP5_Baseline!$C:$C,Results_list!$C$25,SSP5_Baseline!$D:$D,Results_list!$D33,SSP5_Baseline!$B:$B,2025)) -> -0.062778743 | N33: =((SUMIFS(SSP5_VSI!$F:$F,SSP5_VSI!$C:$C,Results_list!$C$25,SSP5_VSI!$D:$D,Results_list!$D33,SSP5_VSI!$B:$B,2040)) - (SUMIFS(SSP5_VSI!$F:$F,SSP5_VSI!$C:$C,Results_list!$C$25,SSP5_VSI!$D:$D,Results_list!$D33,SSP5_VSI!$B:$B,2025))) / (SUMIFS(SSP5_VSI!$F:$F,SSP5_VSI!$C:$C,Results_list!$C$25,SSP5_VSI!$D:$D,Results_list!$D33,SSP5_VSI!$B:$B,2025)) -> -0.0627621 | O33: =ROUND(N33-M33,2) -> 0
